Workbook

Sheet Нач.инв.
A1: Помещение
A2: Статья расходов | B2: Стоимость, руб.
A3: Проект вентиляции и ее могнтаж | B3: 100000
A4: Проект электропроводки и его выполнение | B4: 50000
A5: Пожарное оснащение | B5: 50000
A6: Ремонт | B6: 300000
A7: Видеонаблюдение | B7: 100000
A8: ИТОГО | B8: =SUM(B3:B7) -> 600000
A11: Игровое место стандарт
A12: Комлектующие | B12: Наименование | C12: Стоимость, руб. | F12: Амортизация стандартного ПК (5лет)
A13: Клавиатура | B13: RAZER BLACKWIDOW | C13: 7000 | F13: Стоимость, руб. | G13: =SUM(C13:C20) -> 87000
A14: Мышь | B14: THUNDER X3TM30 | C14: 1500 | F14: Ежегодная амортизация, руб. | G14: =G13/5 -> 17400
A15: Коврик | B15: THUNDER X3TMP40 | C15: 500 | F15: Ежемесячная амортизация, руб. | G15: =G14/30 -> 580
A16: Наушники | B16: RAZER KRAKEN | C16: 3000
A17: Процессор | B17: INTEL CORE i-5 9600k | C17: 17500
A18: Видеокарта | B18: NVIDIA RTX 2070 | C18: 36000
A19: Оперативная память | B19: 16 Gb DDR4 | C19: 7500
A20: Монитор | B20: ACER Nitro VG240Ybmipx 23.8" | C20: 14000
A21: ПО | B21: Windows 10 Pro | C21: 22000
A22: Игровое кресло | B22: DXRacer | C22: 30000
A23: Стол компьютерный | B23: Стол для ПК | C23: 5000
B24: ИТОГО | C24: =SUM(C13:C23) -> 144000
A27: Игровое место VIP
A28: Комлектующие | B28: Наименование | C28: Стоимость, руб. | F28: Амортизация VIP ПК (5лет)
A29: Клавиатура | B29: ASUS ROG CLAYMORE | C29: 9000 | F29: Стоимость, руб. | G29: =SUM(C29:C36) -> 165100
A30: Мышь | B30: ASUS ROG GLADIUS 2 | C30: 4000 | F30: Ежегодная амортизация, руб. | G30: =G29/5 -> 33020
A31: Коврик | B31: ASUS ROG SCABBARD | C31: 2600 | F31: Ежемесячная амортизация, руб. | G31: =G30/30 -> 1100.6667
A32: Наушники | B32: ASUS ROG DELTA | C32: 10000
A33: Процессор | B33: INTEL CORE i-9 9700k | C33: 35000
A34: Видеокарта | B34: MSI RTX 2080 | C34: 60000
A35: Оперативная память | B35: 16 Gb DDR4 | C35: 7500
A36: Монитор | B36: ASUS ROG Strix XG248Q 240 ГЦ, 24 “ | C36: 37000
A37: ПО | B37: Windows 10 Pro | C37: 22000
A38: Игровое кресло | B38: DXRacer | C38: 30000
A39: Стол компьютерный | B39: Стол для ПК | C39: 5000
B40: ИТОГО | C40: =SUM(C29:C39) -> 222100
A43: PS4+VR
A44: Комлектующие | B44: Наименование | C44: Цена, руб. | D44: Кол-во | E44: Стоимость, руб. | G44: Амортизация ТВ (5лет)
A45: PS4 | B45: - | C45: 26000 | D45: 2 | E45: =C45*D45 -> 52000 | G45: Стоимость, руб. | H45: =E47 -> 150000
A46: Sony PlayStation VR (CUH-ZVR2) + PlayStation Camera | B46: - | C46: 34000 | D46: 1 | E46: =C46*D46 -> 34000 | G46: Ежегодная амортизация, руб. | H46: =H45/5 -> 30000
...

Sheet Операц.изд. в мес.
A1: Заработная плата
A2: Должность | B2: Оклад, руб. | C2: Кол-во | D2: З/П, руб | E2: Отчисления ЕСН | F2: Стоимость, руб.
A3: Управляющий | B3: 35000 | C3: 1 | D3: =C3*B3 -> 35000 | E3: =D3*$I$4 -> 10500 | F3: =D3+E3 -> 45500
A4: Администратор | B4: 26000 | C4: 3 | D4: =C4*B4 -> 78000 | E4: =D4*$I$4 -> 23400 | F4: =D4+E4 -> 101400 | H4: ЕСН | I4: 0.3
A5: ИТ-специалист | B5: 40000 | C5: 1 | D5: =C5*B5 -> 40000 | E5: =D5*$I$4 -> 12000 | F5: =D5+E5 -> 52000
A6: Кальянщик | B6: 25000 | C6: 1 | D6: =C6*B6 -> 25000 | E6: =D6*$I$4 -> 7500 | F6: =D6+E6 -> 32500
A7: Уборщица | B7: 15000 | C7: 1 | D7: =C7*B7 -> 15000 | E7: =D7*$I$4 -> 4500 | F7: =D7+E7 -> 19500
D8: =SUM(D3:D7) -> 193000
E10: Аутсорсинг
E11: Бухгалтерия | F11: 1500
E12: ИТОГО | F12: =SUM(F3:F7)+F11 -> 252400
A17: Операционные затраты
A18: Статья расхода | B18: Сумма, руб.
A19: З/п | B19: =F12 -> 252400
A20: Аренда | B20: 150000
A21: Электричество и интернет | B21: 50000
A22: Покупка еды и напитков | B22: 10000
A23: Непредвиденное | B23: 15000
A24: ИТОГО | B24: =SUM(B19:B23) -> 477400

Sheet Инв.расчет
C1: CAPEX (ИНВЕСТИЦИИ)
D2: ед. изм. | E2: Кол-во | F2: Цена за ед., руб. | G2: Стоимость
C3: ПОМЕЩЕНИЕ | G3: =SUM(G4:G8) -> 600000
C4: Проект вентиляции и ее могнтаж | D4: работ | E4: 1 | F4: =Нач.инв.!B3 -> 100000 | G4: =E4*F4 -> 100000
C5: Проект электропроводки и его выполнение | D5: работ | E5: 1 | F5: =Нач.инв.!B4 -> 50000 | G5: =E5*F5 -> 50000
C6: Пожарное оснащение | D6: работ | E6: 1 | F6: =Нач.инв.!B5 -> 50000 | G6: =E6*F6 -> 50000
C7: Ремонт | D7: работ | E7: 1 | F7: =Нач.инв.!B6 -> 300000 | G7: =E7*F7 -> 300000
C8: Видеонаблюдение | D8: работ | E8: 1 | F8: =Нач.инв.!B7 -> 100000 | G8: =E8*F8 -> 100000
C10: Оборудование игровых мест | G10: =SUM(G11:G15) -> 2803100
C11: ПК стандарт+мебель | D11: 1 место | E11: ='Вход и предположения'!E4 -> 10 | F11: =Нач.инв.!C24 -> 144000 | G11: =E11*F11 -> 1440000
C12: ПК VIP+мебель | D12: 1 место | E12: ='Вход и предположения'!E5 -> 5 | F12: =Нач.инв.!C40 -> 222100 | G12: =E12*F12 -> 1110500
C13: PS4+мебель | D13: 1 место | E13: ='Вход и предположения'!E6 -> 2 | F13: =Нач.инв.!C45+Нач.инв.!C47+Нач.инв.!C61+Нач.инв.!C58 -> 84300 | G13: =E13*F13 -> 168600
C14: VR | D14: 1 место | E14: 1 | F14: =Нач.инв.!C46 -> 34000 | G14: =E14*F14 -> 34000
C15: ТВ | D15: 1 место | E15: 1 | F15: =Нач.инв.!C47 -> 50000 | G15: =E15*F15 -> 50000
C17: Зона кафе и администратора | G17: =SUM(G18:G26) -> 219200
C18: Компьютер администратора | D18: шт. | E18: 1 | F18: 50000 | G18: =E18*F18 -> 50000
C19: Кресло администратора | D19: шт. | E19: 1 | F19: 4600 | G19: =E19*F19 -> 4600
C20: Стойка администратора | D20: шт. | E20: 1 | F20: 30000 | G20: =E20*F20 -> 30000
C21: Принтер | D21: шт. | E21: 1 | F21: 5600 | G21: =E21*F21 -> 5600
C22: Онлайн касса | D22: шт. | E22: 1 | F22: 20000 | G22: =E22*F22 -> 20000
C23: Стол кафе | D23: шт. | E23: 4 | F23: 1500 | G23: =E23*F23 -> 6000
C24: Минидиваны | D24: шт. | E24: 8 | F24: 5000 | G24: =E24*F24 -> 40000
C25: Оборудование кафе | D25: шт. | E25: 1 | F25: 35000 | G25: =E25*F25 -> 35000
C26: Кальяны | D26: шт. | E26: 7 | F26: 4000 | G26: =E26*F26 -> 28000
C28: ИНВЕСТИЦИИ ВСЕГО | G28: =SUM(G3,G10,G17) -> 3622300

Sheet Вход и предположения
C1: ВВОДНЫЕ ДАННЫЕ / ASSUMPTIONS
C3: UNIT | D3: Ед. изм. | E3: Значение
C4: Количество стандартных PC | D4: шт. | E4: 10
C5: Количество PC Boot Camp (VIP) | D5: шт. | E5: 5
C6: Количество Sony PS + TV | D6: шт. | E6: 2
C7: Площадь помещения | D7: м2 | E7: 200
C9: REVENUE
E10: 1 год | F10: 2 год | G10: 3 год | H10: 4 год | I10: 5 год | L10: tax rate | M10: =E28 -> 0.15
C11: % загрузки PC | D11: % | E11: 0.4 | F11: 0.5 | G11: 0.5 | H11: 0.5 | I11: 0.5 | L11: rf | M11: ='re и wacc'!H24 -> 0.06245
C12: % загрузки PC VIP | D12: % | E12: 0.4 | F12: 0.5 | G12: 0.5 | H12: 0.5 | I12: 0.5 | L12: rd | M12: 0.075
C13: % загрузки Sony PS + TV Led | D13: % | E13: 0.4 | F13: 0.5 | G13: 0.5 | H13: 0.5 | I13: 0.5 | L13: re | M13: ='re и wacc'!C22 -> 0.16245
L14: wacc | M14: ='re и wacc'!C40 -> 0.13520212
C15: Средняя стоимость часа игры PC | D15: руб./час. | E15: 100
C16: Средняя стоимость часа игры PC VIP | D16: руб./час. | E16: 110 | L16: g | M16: 0.065 | N16: Исследование PwC
C17: Средняя стоимость часа игры Sony PS | D17: руб./час. | E17: 200
C18: Рублей выручки бара на 1 час игрового времени | D18: руб./час. | E18: 70
C19: Прочие доходы | D19: руб./мес. | E19: 15000
C21: OPEX (операционные расходы)
C22: Ставка аренды помещения (фикс ставка/постоянная часть) | D22: руб./м2 год | E22: 9000
C24: % роста годовой арендной ставки помещения | D24: % в год | E24: 0.05
C25: Доля прочих затрат (мелкие затраты) | D25: % от затрат | E25: 0.03
C26: Отношение оборотного капитала к выручке | D26: % | E26: 0.1
C27: Комаунальные платежи (вода) | D27: руб. | E27: 2500
C28: Ставка УСН (доходы-расходы) | D28: % | E28: 0.15
C29: Сумма официальной з/п в мес. | D29: руб./мес. | E29: ='Операц.изд. в мес.'!D8 -> 193000
C30: % затрат на рекламу от выручки | D30: % от выручки | E30: 0.02
C31: Маржинальность бара / % наценки | D31: % | E31: 1.1
C32: Затраты на интернет и электричество в мес. | D32: тыс.руб/мес. | E32: ='Операц.изд. в мес.'!B21 -> 50000
C34: Доля карточных платежей от выручки | D34: % | E34: 0.4
C35: Комиссия за эквайринг | D35: % | E35: 0.02
C37: Бухгалтерское обсулживание | D37: руб./мес. | E37: ='Операц.изд. в мес.'!F11 -> 1500
C39: Отношение кап затрат к выручке | E39: 0.02
E42: 1 год | F42: 2 год | G42: 3 год | H42: 4 год | I42: 5 год
C43: Инфляция | E43: 0 | F43: 0.04 | G43: 0.04 | H43: 0.04 | I43: 0.04
C50: Кредит на сумму 1млн.руб под 7,5% годовых | D50: 1000000
C52: По месяцам
C53: Период | D53: 0 | E53: 1 | F53: 2 | G53: 3 | H53: 4 | I53: 5 | J53: 6 | K53: 7 | L53: 8 | M53: 9 | N53: 10 | O53: 11 | P53: 12 | Q53: 13 | R53: 14 | S53: 15 | T53: 16 | U53: 17 | V53: 18 | W53: 19 | X53: 20 | Y53: 21 | Z53: 22 | AA53: 23 | AB53: 24 | AC53: 25 | AD53: 26 | AE53: 27 | AF53: 28 | AG53: 29 | AH53: 30 | AI53: 31 | AJ53: 32 | AK53: 33 | AL53: 34 | AM53: 35 | AN53: 36
C54: Платеж | D54: =D55+D56 -> 0 | E54: =E55+E56 -> 34027.778 | F54: =F55+F56 -> 33854.167 | G54: =G55+G56 -> 33680.556 | H54: =H55+H56 -> 33506.944 | I54: =I55+I56 -> 33333.333 | J54: =J55+J56 -> 33159.722 | K54: =K55+K56 -> 32986.111 | ... AN54: =AN55+AN56 -> 27951.389
C55: Процент | D55: 0 | E55: =D57*$M$12/12 -> 6250 | F55: =E57*$M$12/12 -> 6076.3889 | G55: =F57*$M$12/12 -> 5902.7778 | H55: =G57*$M$12/12 -> 5729.1667 | I55: =H57*$M$12/12 -> 5555.5556 | J55: =I57*$M$12/12 -> 5381.9444 | K55: =J57*$M$12/12 -> 5208.3333 | L55: =K57*$M$12/12 -> 5034.7222 | ... AN55: =AM57*$M$12/12 -> 173.61111
C56: Тело | D56: 0 | E56: =$D$50/36 -> 27777.778 | F56: =$D$50/36 -> 27777.778 | G56: =$D$50/36 -> 27777.778 | H56: =$D$50/36 -> 27777.778 | I56: =$D$50/36 -> 27777.778 | J56: =$D$50/36 -> 27777.778 | K56: =$D$50/36 -> 27777.778 | L56: =$D$50/36 -> 27777.778 | ... AN56: =$D$50/36 -> 27777.778
...

Sheet Модель
C1: МОДЕЛЬ
E3: 1 | F3: 1 | G3: 1 | H3: 1 | I3: 1 | J3: 1 | K3: 1 | L3: 1 | M3: 1 | N3: 1 | O3: 1 | P3: 1 | Q3: 1 | R3: 1 | S3: 1 | T3: 1 | U3: 1 | V3: 1 | W3: 1 | X3: 1 | Y3: 1 | Z3: 1 | AA3: 1 | AB3: 1 | AC3: 1 | AD3: 1 | AE3: 1 | AF3: 1 | AG3: 1 | AH3: 1 | AI3: 1 | AJ3: 1 | AK3: 1 | AL3: 1 | AM3: 1 | AN3: 1 | AO3: 1 | AP3: 1 | AQ3: 1 | AR3: 1 | AS3: 1 | AT3: 1 | AU3: 1 | AV3: 1 | AW3: 1 | AX3: 1 | AY3: 1 | AZ3: 1 | BA3: 1 | BB3: 1 | BC3: 1 | BD3: 1 | BE3: 1 | BF3: 1 | BG3: 1 | BH3: 1 | BI3: 1 | BJ3: 1 | BK3: 1 | BL3: 1 | BM3: 1
C4: Годовая инфляция | D4: % | F4: ='Вход и предположения'!$E$43 -> 0 | G4: ='Вход и предположения'!$E$43 -> 0 | H4: ='Вход и предположения'!$E$43 -> 0 | I4: ='Вход и предположения'!$E$43 -> 0 | J4: ='Вход и предположения'!$E$43 -> 0 | K4: ='Вход и предположения'!$E$43 -> 0 | L4: ='Вход и предположения'!$E$43 -> 0 | M4: ='Вход и предположения'!$E$43 -> 0 | ... Q4: ='Вход и предположения'!$E$43 -> 0 | R4: ='Вход и предположения'!$F$43 -> 0.04 | S4: ='Вход и предположения'!$F$43 -> 0.04 | T4: ='Вход и предположения'!$F$43 -> 0.04 | U4: ='Вход и предположения'!$F$43 -> 0.04 | V4: ='Вход и предположения'!$F$43 -> 0.04 | W4: ='Вход и предположения'!$F$43 -> 0.04 | X4: ='Вход и предположения'!$F$43 -> 0.04 | Y4: ='Вход и предположения'!$F$43 -> 0.04 | ... AC4: ='Вход и предположения'!$F$43 -> 0.04 | AD4: ='Вход и предположения'!$G$43 -> 0.04 | AE4: ='Вход и предположения'!$G$43 -> 0.04 | AF4: ='Вход и предположения'!$G$43 -> 0.04 | AG4: ='Вход и предположения'!$G$43 -> 0.04 | AH4: ='Вход и предположения'!$G$43 -> 0.04 | AI4: ='Вход и предположения'!$G$43 -> 0.04 | AJ4: ='Вход и предположения'!$G$43 -> 0.04 | AK4: ='Вход и предположения'!$G$43 -> 0.04 | ... AO4: ='Вход и предположения'!$G$43 -> 0.04 | AP4: ='Вход и предположения'!$H$43 -> 0.04 | AQ4: ='Вход и предположения'!$H$43 -> 0.04 | AR4: ='Вход и предположения'!$H$43 -> 0.04 | AS4: ='Вход и предположения'!$H$43 -> 0.04 | AT4: ='Вход и предположения'!$H$43 -> 0.04 | AU4: ='Вход и предположения'!$H$43 -> 0.04 | AV4: ='Вход и предположения'!$H$43 -> 0.04 | AW4: ='Вход и предположения'!$H$43 -> 0.04 | ... BA4: ='Вход и предположения'!$H$43 -> 0.04 | BB4: ='Вход и предположения'!$I$43 -> 0.04 | BC4: ='Вход и предположения'!$I$43 -> 0.04 | BD4: ='Вход и предположения'!$I$43 -> 0.04 | BE4: ='Вход и предположения'!$I$43 -> 0.04 | BF4: ='Вход и предположения'!$I$43 -> 0.04 | BG4: ='Вход и предположения'!$I$43 -> 0.04 | BH4: ='Вход и предположения'!$I$43 -> 0.04 | BI4: ='Вход и предположения'!$I$43 -> 0.04 | ... BM4: ='Вход и предположения'!$I$43 -> 0.04
C5: Инфляция периода | D5: % | F5: =F4/12 -> 0 | G5: =G4/12 -> 0 | H5: =H4/12 -> 0 | I5: =I4/12 -> 0 | J5: =J4/12 -> 0 | K5: =K4/12 -> 0 | L5: =L4/12 -> 0 | M5: =M4/12 -> 0 | ... BM5: =BM4/12 -> 0.0033333333
C6: Накопленная инфляция | D6: % | E6: 1 | F6: =E6*(1+F5) -> 1 | G6: =F6*(1+G5) -> 1 | H6: =G6*(1+H5) -> 1 | I6: =H6*(1+I5) -> 1 | J6: =I6*(1+J5) -> 1 | K6: =J6*(1+K5) -> 1 | L6: =K6*(1+L5) -> 1 | M6: =L6*(1+M5) -> 1 | ... BM6: =BL6*(1+BM5) -> 1.1731987
C7: Среднее количество часов в месяце всего 1PC | D7: часов/1PC | F7: =24*30 -> 720 | G7: =24*30 -> 720 | H7: =24*30 -> 720 | I7: =24*30 -> 720 | J7: =24*30 -> 720 | K7: =24*30 -> 720 | L7: =24*30 -> 720 | M7: =24*30 -> 720 | ... BM7: =24*30 -> 720
C8: Период | E8: 0 | F8: 1 | G8: 2 | H8: 3 | I8: 4 | J8: 5 | K8: 6 | L8: 7 | M8: 8 | N8: 9 | O8: 10 | P8: 11 | Q8: 12 | R8: 13 | S8: 14 | T8: 15 | U8: 16 | V8: 17 | W8: 18 | X8: 19 | Y8: 20 | Z8: 21 | AA8: 22 | AB8: 23 | AC8: 24 | AD8: 25 | AE8: 26 | AF8: 27 | AG8: 28 | AH8: 29 | AI8: 30 | AJ8: 31 | AK8: 32 | AL8: 33 | AM8: 34 | AN8: 35 | AO8: 36 | AP8: 37 | AQ8: 38 | AR8: 39 | AS8: 40 | AT8: 41 | AU8: 42 | AV8: 43 | AW8: 44 | AX8: 45 | AY8: 46 | AZ8: 47 | BA8: 48 | BB8: 49 | BC8: 50 | BD8: 51 | BE8: 52 | BF8: 53 | BG8: 54 | BH8: 55 | BI8: 56 | BJ8: 57 | BK8: 58 | BL8: 59 | BM8: 60
C9: REVENUE | D9: Ед. изм. | BP9: 1 год | BQ9: 2 год | BR9: 3 год | BS9: 4 год | BT9: 5 год | BU9: Всего
C10: Выручка от аренды стандартных PC | F10: =F11*F14*F15 -> 144000 | G10: =G11*G14*G15 -> 216000 | H10: =H11*H14*H15 -> 252000 | I10: =I11*I14*I15 -> 288000 | J10: =J11*J14*J15 -> 288000 | K10: =K11*K14*K15 -> 288000 | L10: =L11*L14*L15 -> 288000 | M10: =M11*M14*M15 -> 288000 | ... BM10: =BM11*BM14*BM15 -> 422351.52 | BO10: =SUM(F10:BM10) -> 21971808 | BP10: =SUM(F10:Q10) -> 3204000 | BQ10: =SUM(R10:AC10) -> 4414753.6 | BR10: =SUM(AD10:AO10) -> 4594617.5 | BS10: =SUM(AP10:BA10) -> 4781809.3 | BT10: =SUM(BB10:BM10) -> 4976627.6 | BU10: =SUM(BP10:BT10) -> 21971808
C11: Количество компьютеров PC | D11: шт. | F11: ='Вход и предположения'!$E$4 -> 10 | G11: ='Вход и предположения'!$E$4 -> 10 | H11: ='Вход и предположения'!$E$4 -> 10 | I11: ='Вход и предположения'!$E$4 -> 10 | J11: ='Вход и предположения'!$E$4 -> 10 | K11: ='Вход и предположения'!$E$4 -> 10 | L11: ='Вход и предположения'!$E$4 -> 10 | M11: ='Вход и предположения'!$E$4 -> 10 | ... BM11: ='Вход и предположения'!$E$4 -> 10
C12: % загрузки PC | D12: % | F12: 0.2 | G12: 0.3 | H12: 0.35 | I12: ='Вход и предположения'!$E$11 -> 0.4 | J12: ='Вход и предположения'!$E$11 -> 0.4 | K12: ='Вход и предположения'!$E$11 -> 0.4 | L12: ='Вход и предположения'!$E$11 -> 0.4 | M12: ='Вход и предположения'!$E$11 -> 0.4 | N12: ='Вход и предположения'!$E$11 -> 0.4 | O12: ='Вход и предположения'!$E$11 -> 0.4 | P12: ='Вход и предположения'!$E$11 -> 0.4 | Q12: ='Вход и предположения'!$E$11 -> 0.4 | R12: ='Вход и предположения'!$F$11 -> 0.5 | S12: ='Вход и предположения'!$F$11 -> 0.5 | T12: ='Вход и предположения'!$F$11 -> 0.5 | U12: ='Вход и предположения'!$F$11 -> 0.5 | V12: ='Вход и предположения'!$F$11 -> 0.5 | W12: ='Вход и предположения'!$F$11 -> 0.5 | X12: ='Вход и предположения'!$F$11 -> 0.5 | Y12: ='Вход и предположения'!$F$11 -> 0.5 | ... AC12: ='Вход и предположения'!$F$11 -> 0.5 | AD12: ='Вход и предположения'!$G$11 -> 0.5 | AE12: ='Вход и предположения'!$G$11 -> 0.5 | AF12: ='Вход и предположения'!$G$11 -> 0.5 | AG12: ='Вход и предположения'!$G$11 -> 0.5 | AH12: ='Вход и предположения'!$G$11 -> 0.5 | AI12: ='Вход и предположения'!$G$11 -> 0.5 | AJ12: ='Вход и предположения'!$G$11 -> 0.5 | AK12: ='Вход и предположения'!$G$11 -> 0.5 | ... AO12: ='Вход и предположения'!$G$11 -> 0.5 | AP12: ='Вход и предположения'!$H$11 -> 0.5 | AQ12: ='Вход и предположения'!$H$11 -> 0.5 | AR12: ='Вход и предположения'!$H$11 -> 0.5 | AS12: ='Вход и предположения'!$H$11 -> 0.5 | AT12: ='Вход и предположения'!$H$11 -> 0.5 | AU12: ='Вход и предположения'!$H$11 -> 0.5 | AV12: ='Вход и предположения'!$H$11 -> 0.5 | AW12: ='Вход и предположения'!$H$11 -> 0.5 | ... BA12: ='Вход и предположения'!$H$11 -> 0.5 | BB12: ='Вход и предположения'!$I$11 -> 0.5 | BC12: ='Вход и предположения'!$I$11 -> 0.5 | BD12: ='Вход и предположения'!$I$11 -> 0.5 | BE12: ='Вход и предположения'!$I$11 -> 0.5 | BF12: ='Вход и предположения'!$I$11 -> 0.5 | BG12: ='Вход и предположения'!$I$11 -> 0.5 | BH12: ='Вход и предположения'!$I$11 -> 0.5 | BI12: ='Вход и предположения'!$I$11 -> 0.5 | ... BM12: ='Вход и предположения'!$I$11 -> 0.5
C13: Средняя стоимость часа игры PC | D13: руб/час | F13: ='Вход и предположения'!$E$15 -> 100 | G13: ='Вход и предположения'!$E$15 -> 100 | H13: ='Вход и предположения'!$E$15 -> 100 | I13: ='Вход и предположения'!$E$15 -> 100 | J13: ='Вход и предположения'!$E$15 -> 100 | K13: ='Вход и предположения'!$E$15 -> 100 | L13: ='Вход и предположения'!$E$15 -> 100 | M13: ='Вход и предположения'!$E$15 -> 100 | ... BM13: ='Вход и предположения'!$E$15 -> 100
C14: Средняя стоимость часа игры PC с инфляцией | D14: руб/час | F14: =F13*F6 -> 100 | G14: =G13*G6 -> 100 | H14: =H13*H6 -> 100 | I14: =I13*I6 -> 100 | J14: =J13*J6 -> 100 | K14: =K13*K6 -> 100 | L14: =L13*L6 -> 100 | M14: =M13*M6 -> 100 | ... BM14: =BM13*BM6 -> 117.31987
C15: Количество часов игрового времени 1 PC | D15: часов /1 PC | F15: =F7*F12 -> 144 | G15: =G7*G12 -> 216 | H15: =H7*H12 -> 252 | I15: =I7*I12 -> 288 | J15: =J7*J12 -> 288 | K15: =K7*K12 -> 288 | L15: =L7*L12 -> 288 | M15: =M7*M12 -> 288 | ... BM15: =BM7*BM12 -> 360
C17: Выручка от PC VIP | F17: =F18*F21*F22 -> 79200 | G17: =G18*G21*G22 -> 118800 | H17: =H18*H21*H22 -> 138600 | I17: =I18*I21*I22 -> 158400 | J17: =J18*J21*J22 -> 158400 | K17: =K18*K21*K22 -> 158400 | L17: =L18*L21*L22 -> 158400 | M17: =M18*M21*M22 -> 158400 | ... BM17: =BM18*BM21*BM22 -> 232293.34 | BO17: =SUM(F17:BM17) -> 12084494 | BP17: =SUM(F17:Q17) -> 1762200 | BQ17: =SUM(R17:AC17) -> 2428114.5 | BR17: =SUM(AD17:AO17) -> 2527039.6 | BS17: =SUM(AP17:BA17) -> 2629995.1 | BT17: =SUM(BB17:BM17) -> 2737145.2 | BU17: =SUM(BP17:BT17) -> 12084494
C18: Количество компьютеров PC | D18: шт. | F18: ='Вход и предположения'!$E$5 -> 5 | G18: ='Вход и предположения'!$E$5 -> 5 | H18: ='Вход и предположения'!$E$5 -> 5 | I18: ='Вход и предположения'!$E$5 -> 5 | J18: ='Вход и предположения'!$E$5 -> 5 | K18: ='Вход и предположения'!$E$5 -> 5 | L18: ='Вход и предположения'!$E$5 -> 5 | M18: ='Вход и предположения'!$E$5 -> 5 | ... BM18: ='Вход и предположения'!$E$5 -> 5
C19: % загрузки PC | D19: % | F19: 0.2 | G19: 0.3 | H19: 0.35 | I19: ='Вход и предположения'!$E$12 -> 0.4 | J19: ='Вход и предположения'!$E$12 -> 0.4 | K19: ='Вход и предположения'!$E$12 -> 0.4 | L19: ='Вход и предположения'!$E$12 -> 0.4 | M19: ='Вход и предположения'!$E$12 -> 0.4 | N19: ='Вход и предположения'!$E$12 -> 0.4 | O19: ='Вход и предположения'!$E$12 -> 0.4 | P19: ='Вход и предположения'!$E$12 -> 0.4 | Q19: ='Вход и предположения'!$E$12 -> 0.4 | R19: ='Вход и предположения'!$F$12 -> 0.5 | S19: ='Вход и предположения'!$F$12 -> 0.5 | T19: ='Вход и предположения'!$F$12 -> 0.5 | U19: ='Вход и предположения'!$F$12 -> 0.5 | V19: ='Вход и предположения'!$F$12 -> 0.5 | W19: ='Вход и предположения'!$F$12 -> 0.5 | X19: ='Вход и предположения'!$F$12 -> 0.5 | Y19: ='Вход и предположения'!$F$12 -> 0.5 | ... AC19: ='Вход и предположения'!$F$12 -> 0.5 | AD19: ='Вход и предположения'!$G$12 -> 0.5 | AE19: ='Вход и предположения'!$G$12 -> 0.5 | AF19: ='Вход и предположения'!$G$12 -> 0.5 | AG19: ='Вход и предположения'!$G$12 -> 0.5 | AH19: ='Вход и предположения'!$G$12 -> 0.5 | AI19: ='Вход и предположения'!$G$12 -> 0.5 | AJ19: ='Вход и предположения'!$G$12 -> 0.5 | AK19: ='Вход и предположения'!$G$12 -> 0.5 | ... AO19: ='Вход и предположения'!$G$12 -> 0.5 | AP19: ='Вход и предположения'!$H$12 -> 0.5 | AQ19: ='Вход и предположения'!$H$12 -> 0.5 | AR19: ='Вход и предположения'!$H$12 -> 0.5 | AS19: ='Вход и предположения'!$H$12 -> 0.5 | AT19: ='Вход и предположения'!$H$12 -> 0.5 | AU19: ='Вход и предположения'!$H$12 -> 0.5 | AV19: ='Вход и предположения'!$H$12 -> 0.5 | AW19: ='Вход и предположения'!$H$12 -> 0.5 | ... BA19: ='Вход и предположения'!$H$12 -> 0.5 | BB19: ='Вход и предположения'!$I$12 -> 0.5 | BC19: ='Вход и предположения'!$I$12 -> 0.5 | BD19: ='Вход и предположения'!$I$12 -> 0.5 | BE19: ='Вход и предположения'!$I$12 -> 0.5 | BF19: ='Вход и предположения'!$I$12 -> 0.5 | BG19: ='Вход и предположения'!$I$12 -> 0.5 | BH19: ='Вход и предположения'!$I$12 -> 0.5 | BI19: ='Вход и предположения'!$I$12 -> 0.5 | ... BM19: ='Вход и предположения'!$I$12 -> 0.5
C20: Средняя стоимость часа игры PC | D20: руб/час | F20: ='Вход и предположения'!$E$16 -> 110 | G20: ='Вход и предположения'!$E$16 -> 110 | H20: ='Вход и предположения'!$E$16 -> 110 | I20: ='Вход и предположения'!$E$16 -> 110 | J20: ='Вход и предположения'!$E$16 -> 110 | K20: ='Вход и предположения'!$E$16 -> 110 | L20: ='Вход и предположения'!$E$16 -> 110 | M20: ='Вход и предположения'!$E$16 -> 110 | ... BM20: ='Вход и предположения'!$E$16 -> 110
C21: Средняя стоимость часа игры PC с инфляцией | D21: руб/час | F21: =F20*F6 -> 110 | G21: =G20*G6 -> 110 | H21: =H20*H6 -> 110 | I21: =I20*I6 -> 110 | J21: =J20*J6 -> 110 | K21: =K20*K6 -> 110 | L21: =L20*L6 -> 110 | M21: =M20*M6 -> 110 | ... BM21: =BM20*BM6 -> 129.05185
C22: Количество часов игрового времени 1 PC | D22: часов /1 PC | F22: =F7*F19 -> 144 | G22: =G7*G19 -> 216 | H22: =H7*H19 -> 252 | I22: =I7*I19 -> 288 | J22: =J7*J19 -> 288 | K22: =K7*K19 -> 288 | L22: =L7*L19 -> 288 | M22: =M7*M19 -> 288 | ... BM22: =BM7*BM19 -> 360
C24: Выручка от аренды Sony PS | F24: =F25*F28*F29 -> 57600 | G24: =G25*G28*G29 -> 86400 | H24: =H25*H28*H29 -> 100800 | I24: =I25*I28*I29 -> 115200 | J24: =J25*J28*J29 -> 115200 | K24: =K25*K28*K29 -> 115200 | L24: =L25*L28*L29 -> 115200 | M24: =M25*M28*M29 -> 115200 | ... BM24: =BM25*BM28*BM29 -> 168940.61 | BO24: =SUM(F24:BM24) -> 8788723.2 | BP24: =SUM(F24:Q24) -> 1281600 | BQ24: =SUM(R24:AC24) -> 1765901.4 | BR24: =SUM(AD24:AO24) -> 1837847 | BS24: =SUM(AP24:BA24) -> 1912723.7 | BT24: =SUM(BB24:BM24) -> 1990651 | BU24: =SUM(BP24:BT24) -> 8788723.2
C25: Количество компьютеров PS | D25: шт. | F25: ='Вход и предположения'!$E$6 -> 2 | G25: ='Вход и предположения'!$E$6 -> 2 | H25: ='Вход и предположения'!$E$6 -> 2 | I25: ='Вход и предположения'!$E$6 -> 2 | J25: ='Вход и предположения'!$E$6 -> 2 | K25: ='Вход и предположения'!$E$6 -> 2 | L25: ='Вход и предположения'!$E$6 -> 2 | M25: ='Вход и предположения'!$E$6 -> 2 | ... BM25: ='Вход и предположения'!$E$6 -> 2
C26: % загрузки PS | D26: % | F26: 0.2 | G26: 0.3 | H26: 0.35 | I26: ='Вход и предположения'!$E$13 -> 0.4 | J26: ='Вход и предположения'!$E$13 -> 0.4 | K26: ='Вход и предположения'!$E$13 -> 0.4 | L26: ='Вход и предположения'!$E$13 -> 0.4 | M26: ='Вход и предположения'!$E$13 -> 0.4 | N26: ='Вход и предположения'!$E$13 -> 0.4 | O26: ='Вход и предположения'!$E$13 -> 0.4 | P26: ='Вход и предположения'!$E$13 -> 0.4 | Q26: ='Вход и предположения'!$E$13 -> 0.4 | R26: ='Вход и предположения'!$F$13 -> 0.5 | S26: ='Вход и предположения'!$F$13 -> 0.5 | T26: ='Вход и предположения'!$F$13 -> 0.5 | U26: ='Вход и предположения'!$F$13 -> 0.5 | V26: ='Вход и предположения'!$F$13 -> 0.5 | W26: ='Вход и предположения'!$F$13 -> 0.5 | X26: ='Вход и предположения'!$F$13 -> 0.5 | Y26: ='Вход и предположения'!$F$13 -> 0.5 | ... AC26: ='Вход и предположения'!$F$13 -> 0.5 | AD26: ='Вход и предположения'!$G$13 -> 0.5 | AE26: ='Вход и предположения'!$G$13 -> 0.5 | AF26: ='Вход и предположения'!$G$13 -> 0.5 | AG26: ='Вход и предположения'!$G$13 -> 0.5 | AH26: ='Вход и предположения'!$G$13 -> 0.5 | AI26: ='Вход и предположения'!$G$13 -> 0.5 | AJ26: ='Вход и предположения'!$G$13 -> 0.5 | AK26: ='Вход и предположения'!$G$13 -> 0.5 | ... AO26: ='Вход и предположения'!$G$13 -> 0.5 | AP26: ='Вход и предположения'!$H$13 -> 0.5 | AQ26: ='Вход и предположения'!$H$13 -> 0.5 | AR26: ='Вход и предположения'!$H$13 -> 0.5 | AS26: ='Вход и предположения'!$H$13 -> 0.5 | AT26: ='Вход и предположения'!$H$13 -> 0.5 | AU26: ='Вход и предположения'!$H$13 -> 0.5 | AV26: ='Вход и предположения'!$H$13 -> 0.5 | AW26: ='Вход и предположения'!$H$13 -> 0.5 | ... BA26: ='Вход и предположения'!$H$13 -> 0.5 | BB26: ='Вход и предположения'!$I$13 -> 0.5 | BC26: ='Вход и предположения'!$I$13 -> 0.5 | BD26: ='Вход и предположения'!$I$13 -> 0.5 | BE26: ='Вход и предположения'!$I$13 -> 0.5 | BF26: ='Вход и предположения'!$I$13 -> 0.5 | BG26: ='Вход и предположения'!$I$13 -> 0.5 | BH26: ='Вход и предположения'!$I$13 -> 0.5 | BI26: ='Вход и предположения'!$I$13 -> 0.5 | ... BM26: ='Вход и предположения'!$I$13 -> 0.5
C27: Средняя стоимость часа игры PS | D27: руб/час | F27: ='Вход и предположения'!$E$17 -> 200 | G27: ='Вход и предположения'!$E$17 -> 200 | H27: ='Вход и предположения'!$E$17 -> 200 | I27: ='Вход и предположения'!$E$17 -> 200 | J27: ='Вход и предположения'!$E$17 -> 200 | K27: ='Вход и предположения'!$E$17 -> 200 | L27: ='Вход и предположения'!$E$17 -> 200 | M27: ='Вход и предположения'!$E$17 -> 200 | ... BM27: ='Вход и предположения'!$E$17 -> 200
C28: Средняя стоимость часа игры PS с инфляцией | D28: руб/час | F28: =F27*F6 -> 200 | G28: =G27*G6 -> 200 | H28: =H27*H6 -> 200 | I28: =I27*I6 -> 200 | J28: =J27*J6 -> 200 | K28: =K27*K6 -> 200 | L28: =L27*L6 -> 200 | M28: =M27*M6 -> 200 | ... BM28: =BM27*BM6 -> 234.63973
C29: Количество часов игрового времени 1 PS | D29: часов /1 PS | F29: =F7*F26 -> 144 | G29: =G7*G26 -> 216 | H29: =H7*H26 -> 252 | I29: =I7*I26 -> 288 | J29: =J7*J26 -> 288 | K29: =K7*K26 -> 288 | L29: =L7*L26 -> 288 | M29: =M7*M26 -> 288 | ... BM29: =BM7*BM26 -> 360
C31: Всего часов игрового времени всех PC / PS | F31: =F11*F15+F18*F22+F25*F29 -> 2448 | G31: =G11*G15+G18*G22+G25*G29 -> 3672 | H31: =H11*H15+H18*H22+H25*H29 -> 4284 | I31: =I11*I15+I18*I22+I25*I29 -> 4896 | J31: =J11*J15+J18*J22+J25*J29 -> 4896 | K31: =K11*K15+K18*K22+K25*K29 -> 4896 | L31: =L11*L15+L18*L22+L25*L29 -> 4896 | M31: =M11*M15+M18*M22+M25*M29 -> 4896 | ... BM31: =BM11*BM15+BM18*BM22+BM25*BM29 -> 6120
C33: Выручка кафе | F33: =F34*F36 -> 171360 | G33: =G34*G36 -> 257040 | H33: =H34*H36 -> 299880 | I33: =I34*I36 -> 342720 | J33: =J34*J36 -> 342720 | K33: =K34*K36 -> 342720 | L33: =L34*L36 -> 342720 | M33: =M34*M36 -> 342720 | ... BM33: =BM34*BM36 -> 502598.31 | BO33: =SUM(F33:BM33) -> 26146451 | BP33: =SUM(F33:Q33) -> 3812760 | BQ33: =SUM(R33:AC33) -> 5253556.8 | BR33: =SUM(AD33:AO33) -> 5467594.8 | BS33: =SUM(AP33:BA33) -> 5690353 | BT33: =SUM(BB33:BM33) -> 5922186.8 | BU33: =SUM(BP33:BT33) -> 26146451
C34: Всего часов игрового времени | D34: часов | F34: =F31 -> 2448 | G34: =G31 -> 3672 | H34: =H31 -> 4284 | I34: =I31 -> 4896 | J34: =J31 -> 4896 | K34: =K31 -> 4896 | L34: =L31 -> 4896 | M34: =M31 -> 4896 | ... BM34: =BM31 -> 6120
C35: Рублей выручки бара на 1 час игрового времени | D35: руб./час. | F35: ='Вход и предположения'!$E$18 -> 70 | G35: ='Вход и предположения'!$E$18 -> 70 | H35: ='Вход и предположения'!$E$18 -> 70 | I35: ='Вход и предположения'!$E$18 -> 70 | J35: ='Вход и предположения'!$E$18 -> 70 | K35: ='Вход и предположения'!$E$18 -> 70 | L35: ='Вход и предположения'!$E$18 -> 70 | M35: ='Вход и предположения'!$E$18 -> 70 | ... BM35: ='Вход и предположения'!$E$18 -> 70
C36: Рублей выручки бара на 1 час игрового времени с инфляцией | D36: руб./час. | F36: =F35*F6 -> 70 | G36: =G35*G6 -> 70 | H36: =H35*H6 -> 70 | I36: =I35*I6 -> 70 | J36: =J35*J6 -> 70 | K36: =K35*K6 -> 70 | L36: =L35*L6 -> 70 | M36: =M35*M6 -> 70 | ... BM36: =BM35*BM6 -> 82.123907
C38: Прочие доходы | D38: руб./мес. | F38: =F40 -> 15000 | G38: =G40 -> 15000 | H38: =H40 -> 15000 | I38: =I40 -> 15000 | J38: =J40 -> 15000 | K38: =K40 -> 15000 | L38: =L40 -> 15000 | M38: =M40 -> 15000 | ... BM38: =BM40 -> 17597.98 | BO38: =SUM(F38:BM38) -> 961991.99 | BP38: =SUM(F38:Q38) -> 180000 | BQ38: =SUM(R38:AC38) -> 183948.07 | BR38: =SUM(AD38:AO38) -> 191442.39 | BS38: =SUM(AP38:BA38) -> 199242.05 | BT38: =SUM(BB38:BM38) -> 207359.48 | BU38: =SUM(BP38:BT38) -> 961991.99
C39: Прочие доходы без инфляции | F39: ='Вход и предположения'!$E$19 -> 15000 | G39: ='Вход и предположения'!$E$19 -> 15000 | H39: ='Вход и предположения'!$E$19 -> 15000 | I39: ='Вход и предположения'!$E$19 -> 15000 | J39: ='Вход и предположения'!$E$19 -> 15000 | K39: ='Вход и предположения'!$E$19 -> 15000 | L39: ='Вход и предположения'!$E$19 -> 15000 | M39: ='Вход и предположения'!$E$19 -> 15000 | ... BM39: ='Вход и предположения'!$E$19 -> 15000
C40: Прочие доходы с инфляцией | F40: =F39*F6 -> 15000 | G40: =G39*G6 -> 15000 | H40: =H39*H6 -> 15000 | I40: =I39*I6 -> 15000 | J40: =J39*J6 -> 15000 | K40: =K39*K6 -> 15000 | L40: =L39*L6 -> 15000 | M40: =M39*M6 -> 15000 | ... BM40: =BM39*BM6 -> 17597.98
C42: TOTAL REVENUE | F42: =F10+F17+F24+F33+F38 -> 467160 | G42: =G10+G17+G24+G33+G38 -> 693240 | H42: =H10+H17+H24+H33+H38 -> 806280 | I42: =I10+I17+I24+I33+I38 -> 919320 | J42: =J10+J17+J24+J33+J38 -> 919320 | K42: =K10+K17+K24+K33+K38 -> 919320 | L42: =L10+L17+L24+L33+L38 -> 919320 | M42: =M10+M17+M24+M33+M38 -> 919320 | ... BM42: =BM10+BM17+BM24+BM33+BM38 -> 1343781.8 | BO42: =SUM(F42:BM42) -> 69953469 | BP42: =SUM(F42:Q42) -> 10240560 | BQ42: =SUM(R42:AC42) -> 14046274 | BR42: =SUM(AD42:AO42) -> 14618541 | BS42: =SUM(AP42:BA42) -> 15214123 | BT42: =SUM(BB42:BM42) -> 15833970 | BU42: =SUM(BP42:BT42) -> 69953469
C44: OPEX
C45: Площадь помещения | D45: м2 | F45: ='Вход и предположения'!$E$7 -> 200 | G45: ='Вход и предположения'!$E$7 -> 200 | H45: ='Вход и предположения'!$E$7 -> 200 | I45: ='Вход и предположения'!$E$7 -> 200 | J45: ='Вход и предположения'!$E$7 -> 200 | K45: ='Вход и предположения'!$E$7 -> 200 | L45: ='Вход и предположения'!$E$7 -> 200 | M45: ='Вход и предположения'!$E$7 -> 200 | ... BM45: ='Вход и предположения'!$E$7 -> 200
C46: Среднее количество рабочих дней | D46: дней | F46: =30 -> 30 | G46: =30 -> 30 | H46: =30 -> 30 | I46: =30 -> 30 | J46: =30 -> 30 | K46: =30 -> 30 | L46: =30 -> 30 | M46: =30 -> 30 | ... BM46: =30 -> 30
C48: Аренда помещения (фиксированная ставка) | F48: =F49*F50*F52/12 -> 150625 | G48: =G49*G50*G52/12 -> 151252.6 | H48: =H49*H50*H52/12 -> 151882.82 | I48: =I49*I50*I52/12 -> 152515.67 | J48: =J49*J50*J52/12 -> 153151.15 | K48: =K49*K50*K52/12 -> 153789.28 | L48: =L49*L50*L52/12 -> 154430.07 | M48: =M49*M50*M52/12 -> 155073.53 | ... BM48: =BM49*BM50*BM52/12 -> 192503.8 | BO48: =SUM(F48:BM48) -> 10243416 | BP48: =SUM(F48:Q48) -> 1849502.6 | BQ48: =SUM(R48:AC48) -> 1944126.7 | BR48: =SUM(AD48:AO48) -> 2043591.9 | BS48: =SUM(AP48:BA48) -> 2148145.9 | BT48: =SUM(BB48:BM48) -> 2258049.1 | BU48: =SUM(BP48:BT48) -> 10243416
C49: Площадь | D49: м2 | F49: =F45 -> 200 | G49: =G45 -> 200 | H49: =H45 -> 200 | I49: =I45 -> 200 | J49: =J45 -> 200 | K49: =K45 -> 200 | L49: =L45 -> 200 | M49: =M45 -> 200 | ... BM49: =BM45 -> 200
...

Sheet Отчетность
A1: Прогнозируемый отчет о прибылях и убытках
B2: 2021 | C2: 2022 | D2: 2023 | E2: 2024 | F2: 2025
A3: Выручка от реализации услуг | B3: =Модель!BP10+Модель!BP17+Модель!BP24 -> 6247800 | C3: =Модель!BQ10+Модель!BQ17+Модель!BQ24 -> 8608769.5 | D3: =Модель!BR10+Модель!BR17+Модель!BR24 -> 8959504.1 | E3: =Модель!BS10+Модель!BS17+Модель!BS24 -> 9324528.1 | F3: =Модель!BT10+Модель!BT17+Модель!BT24 -> 9704423.7
A4: Выручка от реализации товаров | B4: =Модель!BP33 -> 3812760 | C4: =Модель!BQ33 -> 5253556.8 | D4: =Модель!BR33 -> 5467594.8 | E4: =Модель!BS33 -> 5690353 | F4: =Модель!BT33 -> 5922186.8
A5: Выручка | B5: =B3+B4 -> 10060560 | C5: =C3+C4 -> 13862326 | D5: =D3+D4 -> 14427099 | E5: =E3+E4 -> 15014881 | F5: =F3+F4 -> 15626611
A6: Себестоимость оказанных услуг (коммуналка+интернет+аренда) | B6: =Модель!BP48+Модель!BP54+Модель!BP68 -> 2479502.6 | C6: =Модель!BQ48+Модель!BQ54+Модель!BQ68 -> 2587944.9 | D6: =Модель!BR48+Модель!BR54+Модель!BR68 -> 2713640.3 | E6: =Модель!BS48+Модель!BS54+Модель!BS68 -> 2845493.1 | F6: =Модель!BT48+Модель!BT54+Модель!BT68 -> 2983807.3
A7: Себестоимость реализованных товаров | B7: =Модель!BP71 -> 1815600 | C7: =Модель!BQ71 -> 2501693.7 | D7: =Модель!BR71 -> 2603616.6 | E7: =Модель!BS71 -> 2709691.9 | F7: =Модель!BT71 -> 2820088.9
A8: Коммерческие/управленческие расходы | B8: =Модель!BP57+Модель!BP64+Модель!BP81+Модель!BP77 -> 3382375 | C8: =Модель!BQ57+Модель!BQ64+Модель!BQ81+Модель!BQ77 -> 3492510.2 | D8: =Модель!BR57+Модель!BR64+Модель!BR81+Модель!BR77 -> 3634804.5 | E8: =Модель!BS57+Модель!BS64+Модель!BS81+Модель!BS77 -> 3782120 | F8: =Модель!BT57+Модель!BT64+Модель!BT81+Модель!BT77 -> 3937012
A9: Прибыль до процентов, налогов и амортизации (EBITDA) | B9: =B5-B6-B7-B8 -> 2383082.4 | C9: =C5-C6-C7-C8 -> 5280177.5 | D9: =D5-D6-D7-D8 -> 5475037.5 | E9: =E5-E6-E7-E8 -> 5677576.1 | F9: =F5-F6-F7-F8 -> 5885702.2
A10: Амортизация | B10: =Нач.инв.!$G$14+Нач.инв.!$G$30+Нач.инв.!$H$46+Нач.инв.!$H$56 -> 90420 | C10: =Нач.инв.!$G$14+Нач.инв.!$G$30+Нач.инв.!$H$46+Нач.инв.!$H$56 -> 90420 | D10: =Нач.инв.!$G$14+Нач.инв.!$G$30+Нач.инв.!$H$46+Нач.инв.!$H$56 -> 90420 | E10: =Нач.инв.!$G$14+Нач.инв.!$G$30+Нач.инв.!$H$46+Нач.инв.!$H$56 -> 90420 | F10: =Нач.инв.!$G$14+Нач.инв.!$G$30+Нач.инв.!$H$46+Нач.инв.!$H$56 -> 90420
A11: Прибыль до процентов и налогов (EBIT) | B11: =B9-B10 -> 2292662.4 | C11: =C9-C10 -> 5189757.5 | D11: =D9-D10 -> 5384617.5 | E11: =E9-E10 -> 5587156.1 | F11: =F9-F10 -> 5795282.2
A12: Процентные расходы | B12: =Модель!BP85 -> 63541.667 | C12: =Модель!BQ85 -> 38541.667 | D12: =Модель!BR85 -> 13541.667 | E12: =Модель!BS85 -> 0 | F12: =Модель!BT85 -> 0
A13: Прочие доходы | B13: =Модель!BP38 -> 180000 | C13: =Модель!BQ38 -> 183948.07 | D13: =Модель!BR38 -> 191442.39 | E13: =Модель!BS38 -> 199242.05 | F13: =Модель!BT38 -> 207359.48
A14: Прибыль до налогообложения (EBT) | B14: =B11-B12+B13 -> 2409120.8 | C14: =C11-C12+C13 -> 5335163.9 | D14: =D11-D12+D13 -> 5562518.2 | E14: =E11-E12+E13 -> 5786398.2 | F14: =F11-F12+F13 -> 6002641.7
A15: Налог на прибыль | B15: =Модель!BP87 -> 363450.7 | C15: =Модель!BQ87 -> 767254.56 | D15: =Модель!BR87 -> 799717.07 | E15: =Модель!BS87 -> 831590.42 | F15: =Модель!BT87 -> 862236.71
A16: Чистая прибыль | B16: =B14-B15 -> 2045670 | C16: =C14-C15 -> 4567909.3 | D16: =D14-D15 -> 4762801.1 | E16: =E14-E15 -> 4954807.8 | F16: =F14-F15 -> 5140405
A20: Прогнозируемый баланс (некоторые статьи)
B21: 2021 | C21: 2022 | D21: 2023 | E21: 2024 | F21: 2025
A22: Основные средства | B22: =Инв.расчет!$G$3+Инв.расчет!$G$10+Инв.расчет!$G$17 -> 3622300 | C22: =Инв.расчет!$G$3+Инв.расчет!$G$10+Инв.расчет!$G$17 -> 3622300 | D22: =Инв.расчет!$G$3+Инв.расчет!$G$10+Инв.расчет!$G$17 -> 3622300 | E22: =Инв.расчет!$G$3+Инв.расчет!$G$10+Инв.расчет!$G$17 -> 3622300 | F22: =Инв.расчет!$G$3+Инв.расчет!$G$10+Инв.расчет!$G$17 -> 3622300
A23: Оборотные средства | B23: =Модель!$E$104*Модель!BP42 -> 1024056 | C23: =Модель!$E$104*Модель!BQ42 -> 1404627.4 | D23: =Модель!$E$104*Модель!BR42 -> 1461854.1 | E23: =Модель!$E$104*Модель!BS42 -> 1521412.3 | F23: =Модель!$E$104*Модель!BT42 -> 1583397
A29: Промежуточные операционные денежные потоки
A30: Operating Results | B30: 2021 | C30: 2022 | D30: 2023 | E30: 2024 | F30: 2025
A31: Выручка от реализации услуг | B31: =B3 -> 6247800 | C31: =C3 -> 8608769.5 | D31: =D3 -> 8959504.1 | E31: =E3 -> 9324528.1 | F31: =F3 -> 9704423.7
A32: Выручка от реализации товаров | B32: =B4 -> 3812760 | C32: =C4 -> 5253556.8 | D32: =D4 -> 5467594.8 | E32: =E4 -> 5690353 | F32: =F4 -> 5922186.8
A33: Выручка | B33: =B5 -> 10060560 | C33: =C5 -> 13862326 | D33: =D5 -> 14427099 | E33: =E5 -> 15014881 | F33: =F5 -> 15626611
A34: Себестоимость оказанных услуг (коммуналка+интернет+аренда) | B34: =B6 -> 2479502.6 | C34: =C6 -> 2587944.9 | D34: =D6 -> 2713640.3 | E34: =E6 -> 2845493.1 | F34: =F6 -> 2983807.3
A35: Себестоимость реализованных товаров | B35: =B7 -> 1815600 | C35: =C7 -> 2501693.7 | D35: =D7 -> 2603616.6 | E35: =E7 -> 2709691.9 | F35: =F7 -> 2820088.9
A36: Коммерческие/управленческие расходы | B36: =B8 -> 3382375 | C36: =C8 -> 3492510.2 | D36: =D8 -> 3634804.5 | E36: =E8 -> 3782120 | F36: =F8 -> 3937012
A37: Прибыль до процентов, налогов и амортизации (EBITDA) | B37: =B9 -> 2383082.4 | C37: =C9 -> 5280177.5 | D37: =D9 -> 5475037.5 | E37: =E9 -> 5677576.1 | F37: =F9 -> 5885702.2
A38: Амортизация | B38: =B10 -> 90420 | C38: =C10 -> 90420 | D38: =D10 -> 90420 | E38: =E10 -> 90420 | F38: =F10 -> 90420
A39: Прибыль до процентов и налогов (EBIT) | B39: =B11 -> 2292662.4 | C39: =C11 -> 5189757.5 | D39: =D11 -> 5384617.5 | E39: =E11 -> 5587156.1 | F39: =F11 -> 5795282.2
A40: Свободный денежный поток без учета долгового бремени:
A41: Чистая операционная прибыль после вычета налога (NOPAT) | B41: =B39-B15 -> 1929211.7 | C41: =C39-C15 -> 4422502.9 | D41: =D39-D15 -> 4584900.4 | E41: =E39-E15 -> 4755565.7 | F41: =F39-F15 -> 4933045.5
A42: Амортизация | B42: =B10 -> 90420 | C42: =C10 -> 90420 | D42: =D10 -> 90420 | E42: =E10 -> 90420 | F42: =F10 -> 90420
A43: Изменение оборотного капитала | B43: 0 | C43: =C23-B23 -> 380571.43 | D43: =D23-C23 -> 57226.689 | E43: =E23-D23 -> 59558.192 | F43: =F23-E23 -> 61984.685
A44: Капитальные расходы | B44: =Модель!D98 -> 3622300 | C44: ='Вход и предположения'!$E$39*Модель!BP42 -> 204811.2 | D44: ='Вход и предположения'!$E$39*Модель!BQ42 -> 280925.49 | E44: ='Вход и предположения'!$E$39*Модель!BR42 -> 292370.82 | F44: ='Вход и предположения'!$E$39*Модель!BS42 -> 304282.46
A45: Свободный денежный поток без использования заемных средств (unlevered FCF) | B45: =B41+B42-B43-B44 -> -1602668.3 | C45: =C41+C42-C43-C44 -> 3927540.3 | D45: =D41+D42-D43-D44 -> 4337168.2 | E45: =E41+E42-E43-E44 -> 4494056.7 | F45: =F41+F42-F43-F44 -> 4657198.4

Sheet re и wacc
A1: Расчет re
A2: Для расчета ставки дисконтирования по кумулятивному методу необходимо рассчитать безрисковую процентную ставку,
A3: премию за риск (степень влияния различных рисков) и провести корректировку на инфляцию. | F3: Бескупонная доходность государственных облигаций (ЦБРФ)
A7: где:
A8: r – ставка дисконтирования;
A9: rf – безрисковая процентная ставка (оценка доходности на основе доходности государственных ценных бумаг (ГКО, ОФЗ));
A10: rp – премия за риски компании;
A11: rс – премия за страновой риск (используется для оценки и сравнения международных компаний);
A12: I – процент инфляции (корректировка на рост потребительских цен). | H12: 0.0569
H13: 0.0602
H14: 0.0622
H15: 0.0645
A16: Вид риска | B16: Интервал оценки | C16: Оценка | D16: Пояснение | H16: 0.0659
A17: Безоисковая ставка (rf) | B17: - | C17: =H24 -> 0.06245 | D17: доходности государственных ценных бумаг (ГКО, ОФЗ) | H17: 0.0676
A18: Размер фирмы | B18: 0-5 | C18: 0.03 | D18: Малый размер компании, незначительная конкуренция | H18: 0.0691
A19: Финансовая структура | B19: 0-5 | C19: 0.03 | D19: Часть капитала заемная, рентабельность в 1-ый год ниже, чем в последующие | H19: 0.0698
A20: Диверсификация | B20: 0-5 | C20: 0.03 | D20: Низкая | H20: 0.0702
A21: Менеджмент | B21: 0-5 | C21: 0.01 | D21: Простая организационная структура | H21: 0.0529
A22: re | B22: - | C22: =SUM(C17:C21) -> 0.16245 | H22: 0.0544
H23: 0.0557
H24: =AVERAGE(H12:H23) -> 0.06245
A27: Расчет WACC
B32: E | C32: =Инв.расчет!G28-'Вход и предположения'!D50 -> 2622300
B33: D | C33: ='Вход и предположения'!D50 -> 1000000
B34: V | C34: =C32+C33 -> 3622300
B35: E/V | C35: =C32/C34 -> 0.72393231
B36: D/V | C36: =C33/C34 -> 0.27606769
B37: re | C37: ='Вход и предположения'!M13 -> 0.16245
B38: rd | C38: ='Вход и предположения'!M12 -> 0.075
B39: tax rate | C39: ='Вход и предположения'!M10 -> 0.15
B40: WACC | C40: =C35*C37+C36*C38*(1-C39) -> 0.13520212

Sheet Стоимость компании
A1: Текущая стоимость промежуточных денежных потоков
A7: Период | B7: 1 | C7: 2 | D7: 3 | E7: 4 | F7: 5
A8: Свободный денежный поток без использования заемных средств (unlevered FCF) | B8: =Отчетность!B45 -> -1602668.3 | C8: =Отчетность!C45 -> 3927540.3 | D8: =Отчетность!D45 -> 4337168.2 | E8: =Отчетность!E45 -> 4494056.7 | F8: =Отчетность!F45 -> 4657198.4
A9: WACC(D/V=0) | B9: =$I$9 -> 0.1176028 | C9: =$I$9 -> 0.1176028 | D9: =$I$9 -> 0.1176028 | E9: =$I$9 -> 0.1176028 | F9: =$I$9 -> 0.1176028 | H9: WACC(D/V=0) | I9: ='re и wacc'!C35*'re и wacc'!C37 -> 0.1176028
A10: Discounted un-FCF | B10: =B8/(1+B9)^B7 -> -1434023.1 | C10: =C8/(1+C9)^C7 -> 3144457.2 | D10: =D8/(1+D9)^D7 -> 3107018.4 | E10: =E8/(1+E9)^E7 -> 2880637.5 | F10: =F8/(1+F9)^F7 -> 2671082.6
C13: PV un-FCF | D13: =SUM(B10:F10) -> 10369173
A17: Промежуточный налоговый щит
A23: Период | B23: 1 | C23: 2 | D23: 3
A24: Оплата процентов | B24: =SUM('Вход и предположения'!E55:P55) -> 63541.667 | C24: =SUM('Вход и предположения'!Q55:AB55) -> 38541.667 | D24: =SUM('Вход и предположения'!AC55:AN55) -> 13541.667
A25: Ставка налога на прибыль | B25: ='Вход и предположения'!$M$10 -> 0.15 | C25: ='Вход и предположения'!$M$10 -> 0.15 | D25: ='Вход и предположения'!$M$10 -> 0.15
A26: Налоговый щит | B26: =B24*B25 -> 9531.25 | C26: =C24*C25 -> 5781.25 | D26: =D24*D25 -> 2031.25
A27: Ставка дисконтирования | B27: ='Вход и предположения'!$M$12 -> 0.075 | C27: ='Вход и предположения'!$M$12 -> 0.075 | D27: ='Вход и предположения'!$M$12 -> 0.075
A28: Текущая стоимость налогового щита | B28: =B26/(1+B27)^B23 -> 8866.2791 | C28: =C26/(1+C27)^C23 -> 5002.7042 | D28: =D26/(1+D27)^D23 -> 1635.0762
C31: PV tax sheild | D31: =SUM(B28:D28) -> 15504.059
A34: Итого Стоимость в прогнозный период
A35: Total Intermediate Term Value=PV of FCF+PV of Interest Tax Shields
B37: Total Intermediate Term Value | D37: =D13+D31 -> 10384677
A47: Un-FCF 2025 | B47: =Отчетность!F45 -> 4657198.4
A48: g | B48: ='Вход и предположения'!M16 -> 0.065
A49: WACC | B49: ='Вход и предположения'!M14 -> 0.13520212
C52: TV | D52: =B47*(1+B48)/(B49-B48) -> 70651946
C54: PV of TV | D54: =D52/(1+B49)^5 -> 37476425
A58: Стоимость операционных активов
A59: Value of Operating Assets=Total Intermediate Term Value+PV of Terminal Value
B61: Value of Operating Asset | D61: =D37+D54 -> 47861102

Sheet Фин.эффективность
A1: Денежные потоки
B2: 1 | C2: 2 | D2: 3 | E2: 4 | F2: 5
A3: FCF | B3: =Модель!BP109 -> 1896967.5 | C3: =Модель!BQ109 -> 4375050.4 | D3: =Модель!BR109 -> 4536586.7 | E3: =Модель!BS109 -> 4717400.2 | F3: =Модель!BT109 -> 4891268.5 | H3: wacc | I3: ='Вход и предположения'!M14 -> 0.13520212
A4: Disc.FCF | B4: =B3/(1+$I$3)^B2 -> 1671039.4 | C4: =C3/(1+$I$3)^C2 -> 3394975.7 | D4: =D3/(1+$I$3)^D2 -> 3101056.2 | E4: =E3/(1+$I$3)^E2 -> 2840599.2 | F4: =F3/(1+$I$3)^F2 -> 2594511.1
A6: SUM DFCF | B6: =SUM(B4:F4) -> 13602182
A9: 1. NPV (чистая приведенная стоимость)
A14: С учетом терминальной стоимости
A15: Инвестиции | B15: =Инв.расчет!G28 -> 3622300
A16: Сумма дисконтированных ден.потоков | B16: =B6 -> 13602182
A17: Дисконтированная терминальная стоимость | B17: ='Стоимость компании'!D54 -> 37476425
A18: NPV | B18: =B16+B17-B15 -> 47456307
A21: Без учета терминальной стоимости
A22: Инвестиции | B22: =Инв.расчет!G28 -> 3622300
A23: Сумма дисконтированных ден.потоков | B23: =B6 -> 13602182
A24: NPV | B24: =B23-B22 -> 9979881.6
A27: 2. IRR (внутренняя норма доходности)
B32: 1 | C32: 2 | D32: 3 | E32: 4 | F32: 5 | G32: TV | H32: Io
A33: FCF | B33: =B3 -> 1896967.5 | C33: =C3 -> 4375050.4 | D33: =D3 -> 4536586.7 | E33: =E3 -> 4717400.2 | F33: =F3 -> 4891268.5 | G33: ='Стоимость компании'!D52 -> 70651946 | H33: =Инв.расчет!G28 -> 3622300
A34: Discounted | B34: =B33/(1+$B$37)^B32 -> 844817.03 | C34: =C33/(1+$B$37)^C32 -> 867738 | D34: =D33/(1+$B$37)^D32 -> 400716.81 | E34: =E33/(1+$B$37)^E32 -> 185572.6 | F34: =F33/(1+$B$37)^F32 -> 85691.038 | G34: =G33/(1+B37)^5 -> 1237764.5 | H34: =-H33 -> -3622300 | I34: =SUM(B34:H34) -> -3.9394945e-07
A36: С учетом TV
A37: IRR | B37: 1.2454181
B40: 1 | C40: 2 | D40: 3 | E40: 4 | F40: 5 | G40: Io
A41: FCF | B41: =B3 -> 1896967.5 | C41: =C3 -> 4375050.4 | D41: =D3 -> 4536586.7 | E41: =E3 -> 4717400.2 | F41: =F3 -> 4891268.5 | G41: =Инв.расчет!G28 -> 3622300
A42: Discounted | B42: =B41/(1+$B$45)^B40 -> 1022188.4 | C42: =C41/(1+$B$45)^C40 -> 1270355.4 | D42: =D41/(1+$B$45)^D40 -> 709810.58 | E42: =E41/(1+$B$45)^E40 -> 397728.82 | F42: =F41/(1+$B$45)^F40 -> 222216.81 | G42: =-G41 -> -3622300 | H42: =SUM(A42:G42) -> -8.0093741e-08
A44: Без учета TV
A45: IRR | B45: 0.85579037
A48: 3. РР (период окупаемости) и DPP
A49: РР | B49: =Модель!B113 -> 17 | C49: мес.
A50: DPP | B50: =Модель!B122 -> 19 | C50: мес.
A53: 4. РI (индекс прибыльности)
A54: PI с учетом TV | B54: =B18/B15 -> 13.101153
A55: PI без учета TV | B55: =B24/B22 -> 2.7551229
A57: 5. IRR-WACC (запас финансовой прочности)
A58: IRR-WACC с учетом TV | B58: =B37-I3 -> 1.110216
A59: IRR-WACC без учета TV | B59: =B45-I3 -> 0.72058825

Sheet Чувств. NPV
A1: Изменяемый фактор | B1: Значение NPV (без учета терминальной стоимости) при изменении фактора на %
B2: -0.3 | C2: -0.2 | D2: -0.1 | E2: 0 | F2: 0.1 | G2: 0.2 | H2: 0.3
A3: Загрузка оборудования | B3: 912564.79 | C3: 3935003.7 | D3: 6957442.6 | E3: =Фин.эффективность!$B$24 -> 9979881.6 | F3: 13002321 | G3: 16024759 | H3: 19047198
A4: Стоимость 1 часа игры | B4: 2755643.8 | C4: 5164620 | D4: 7575939.6 | E4: =Фин.эффективность!$B$24 -> 9979881.6 | F4: 12383824 | G4: 14787766 | H4: 17191707
A5: Выручка бара на 1 час времени | B5: 7800995.2 | C5: 8527290.7 | D5: 9253586.1 | E5: =Фин.эффективность!$B$24 -> 9979881.6 | F5: 10706177 | G5: 11432472 | H5: 12158768
A6: Сумма официальной заработной платы | B6: 12917572 | C6: 11938342 | D6: 10959112 | E6: =Фин.эффективность!$B$24 -> 9979881.6 | F6: 9000651.3 | G6: 8021421 | H6: 7034568.3
A7: Затраты на электричество и интернет | B7: 10561620 | C7: 10367707 | D7: 10173794 | E7: =Фин.эффективность!$B$24 -> 9979881.6 | F7: 9785968.9 | G7: 9592056.1 | H7: 9398143.4
A8: Налоговая ставка | B8: 9945394.1 | C8: 9956875.3 | D8: 9968371.1 | E8: =Фин.эффективность!$B$24 -> 9979881.6 | F8: 9991406.7 | G8: 10002946 | H8: 10014501
A9: Стоимость собственного капитала (re) | B9: 11388888 | C9: 10895913 | D9: 10426727 | E9: =Фин.эффективность!$B$24 -> 9979881.6 | F9: 9554033.1 | G9: 9147934.2 | H9: 8760425.5
A10: Стоимость заемного капитала (rd) | B10: 10202499 | C10: 10127777 | D10: 10053573 | E10: =Фин.эффективность!$B$24 -> 9979881.6 | F10: 9906698.3 | G10: 9834018.6 | H10: 9761837.9
A11: Ставка роста (g) | B11: 38772430 | C11: 41214782 | D11: 44071080 | E11: =Фин.эффективность!B18 -> 47456307 | F11: 51532373 | G11: 56534784 | H11: 62819810 | I11: NPV с учетом TV
A14: Изменяемый фактор | B14: Изменение NPV (без учета терминальной стоимости) при изменении фактора на %
B15: -0.3 | C15: -0.2 | D15: -0.1 | E15: 0 | F15: 0.1 | G15: 0.2 | H15: 0.3
A16: Загрузка оборудования | B16: =B3-$E$3 -> -9067316.8 | C16: =C3-$E$3 -> -6044877.9 | D16: =D3-$E$3 -> -3022438.9 | E16: =E3-$E$3 -> 0 | F16: =F3-$E$3 -> 3022438.9 | G16: =G3-$E$3 -> 6044877.9 | H16: =H3-$E$3 -> 9067316.8
A17: Стоимость 1 часа игры | B17: =B4-$E$3 -> -7224237.8 | C17: =C4-$E$3 -> -4815261.6 | D17: =D4-$E$3 -> -2403942 | E17: =E4-$E$3 -> 0 | F17: =F4-$E$3 -> 2403942 | G17: =G4-$E$3 -> 4807883.9 | H17: =H4-$E$3 -> 7211825.9
A18: Выручка бара на 1 час времени | B18: =B5-$E$3 -> -2178886.3 | C18: =C5-$E$3 -> -1452590.9 | D18: =D5-$E$3 -> -726295.44 | E18: =E5-$E$3 -> 0 | F18: =F5-$E$3 -> 726295.44 | G18: =G5-$E$3 -> 1452590.9 | H18: =H5-$E$3 -> 2178886.3
A19: Сумма официальной заработной платы | B19: =B6-$E$3 -> 2937690.9 | C19: =C6-$E$3 -> 1958460.6 | D19: =D6-$E$3 -> 979230.29 | E19: =E6-$E$3 -> 0 | F19: =F6-$E$3 -> -979230.29 | G19: =G6-$E$3 -> -1958460.6 | H19: =H6-$E$3 -> -2945313.2
A20: Затраты на электричество и интернет | B20: =B7-$E$3 -> 581738.15 | C20: =C7-$E$3 -> 387825.43 | D20: =D7-$E$3 -> 193912.72 | E20: =E7-$E$3 -> 0 | F20: =F7-$E$3 -> -193912.72 | G20: =G7-$E$3 -> -387825.43 | H20: =H7-$E$3 -> -581738.15
A21: Налоговая ставка | B21: =B8-$E$3 -> -34487.5 | C21: =C8-$E$3 -> -23006.265 | D21: =D8-$E$3 -> -11510.44 | E21: =E8-$E$3 -> 0 | F21: =F8-$E$3 -> 11525.078 | G21: =G8-$E$3 -> 23064.819 | H21: =H8-$E$3 -> 34619.246
A22: Стоимость собственного капитала (re) | B22: =B9-$E$3 -> 1409006.3 | C22: =C9-$E$3 -> 916031.82 | D22: =D9-$E$3 -> 446845.67 | E22: =E9-$E$3 -> 0 | F22: =F9-$E$3 -> -425848.51 | G22: =G9-$E$3 -> -831947.36 | H22: =H9-$E$3 -> -1219456.1
A23: Стоимость заемного капитала (rd) | B23: =B10-$E$3 -> 222617.32 | C23: =C10-$E$3 -> 147895.68 | D23: =D10-$E$3 -> 73691.458 | E23: =E10-$E$3 -> 0 | F23: =F10-$E$3 -> -73183.304 | G23: =G10-$E$3 -> -145863.01 | H23: =H10-$E$3 -> -218043.63
A24: Ставка роста (g) | B24: =B11-$E$11 -> -8683876.9 | C24: =C11-$E$11 -> -6241525 | D24: =D11-$E$11 -> -3385226.6 | E24: =E11-$E$11 -> 0 | F24: =F11-$E$11 -> 4076066.2 | G24: =G11-$E$11 -> 9078476.7 | H24: =H11-$E$11 -> 15363503 | I24: NPV с учетом TV
A27: Изменяемый фактор | B27: Изменение NPV (без учета терминальной стоимости) при изменении фактора на %
B28: -0.3 | C28: -0.2 | D28: -0.1 | E28: 0 | F28: 0.1 | G28: 0.2 | H28: 0.3
A29: Загрузка оборудования | B29: =B3/$E$3-1 -> -0.90855956 | C29: =C3/$E$3-1 -> -0.60570637 | D29: =D3/$E$3-1 -> -0.30285319 | E29: =E3/$E$3-1 -> 0 | F29: =F3/$E$3-1 -> 0.30285319 | G29: =G3/$E$3-1 -> 0.60570637 | H29: =H3/$E$3-1 -> 0.90855956
A30: Стоимость 1 часа игры | B30: =B4/$E$3-1 -> -0.72388011 | C30: =C4/$E$3-1 -> -0.48249687 | D30: =D4/$E$3-1 -> -0.24087881 | E30: =E4/$E$3-1 -> 0 | F30: =F4/$E$3-1 -> 0.24087881 | G30: =G4/$E$3-1 -> 0.48175761 | H30: =H4/$E$3-1 -> 0.72263642
A31: Выручка бара на 1 час времени | B31: =B5/$E$3-1 -> -0.21832787 | C31: =C5/$E$3-1 -> -0.14555192 | D31: =D5/$E$3-1 -> -0.072775958 | E31: =E5/$E$3-1 -> 0 | F31: =F5/$E$3-1 -> 0.072775958 | G31: =G5/$E$3-1 -> 0.14555192 | H31: =H5/$E$3-1 -> 0.21832787
A32: Сумма официальной заработной платы | B32: =B6/$E$3-1 -> 0.2943613 | C32: =C6/$E$3-1 -> 0.19624086 | D32: =D6/$E$3-1 -> 0.098120432 | E32: =E6/$E$3-1 -> 0 | F32: =F6/$E$3-1 -> -0.098120432 | G32: =G6/$E$3-1 -> -0.19624086 | H32: =H6/$E$3-1 -> -0.29512507
A33: Затраты на электричество и интернет | B33: =B7/$E$3-1 -> 0.058291087 | C33: =C7/$E$3-1 -> 0.038860725 | D33: =D7/$E$3-1 -> 0.019430362 | E33: =E7/$E$3-1 -> 0 | F33: =F7/$E$3-1 -> -0.019430362 | G33: =G7/$E$3-1 -> -0.038860725 | H33: =H7/$E$3-1 -> -0.058291087
A34: Налоговая ставка | B34: =B8/$E$3-1 -> -0.0034557023 | C34: =C8/$E$3-1 -> -0.0023052643 | D34: =D8/$E$3-1 -> -0.0011533644 | E34: =E8/$E$3-1 -> 0 | F34: =F8/$E$3-1 -> 0.0011548312 | G34: =G8/$E$3-1 -> 0.0023111316 | H34: =H8/$E$3-1 -> 0.0034689035
A35: Стоимость собственного капитала (re) | B35: =B9/$E$3-1 -> 0.14118467 | C35: =C9/$E$3-1 -> 0.091787845 | D35: =D9/$E$3-1 -> 0.044774646 | E35: =E9/$E$3-1 -> 0 | F35: =F9/$E$3-1 -> -0.042670698 | G35: =G9/$E$3-1 -> -0.083362448 | H35: =H9/$E$3-1 -> -0.12219144
A36: Стоимость заемного капитала (rd) | B36: =B10/$E$3-1 -> 0.022306609 | C36: =C10/$E$3-1 -> 0.014819382 | D36: =D10/$E$3-1 -> 0.0073840013 | E36: =E10/$E$3-1 -> 0 | F36: =F10/$E$3-1 -> -0.0073330834 | G36: =G10/$E$3-1 -> -0.014615706 | H36: =H10/$E$3-1 -> -0.021848318
A37: Ставка роста (g) | B37: =B11/$E$11-1 -> -0.18298678 | C37: =C11/$E$11-1 -> -0.13152151 | D37: =D11/$E$11-1 -> -0.071333544 | E37: =E11/$E$11-1 -> 0 | F37: =F11/$E$11-1 -> 0.085890926 | G37: =G11/$E$11-1 -> 0.19130179 | H37: =H11/$E$11-1 -> 0.32373996 | I37: NPV с учетом TV

Sheet Сценарии
A1: Сценарий | B1: Пессимистичный | C1: Наиболее вероятный | D1: Оптимистичный
A2: Вероятность реализации | B2: 0.2 | C2: 0.6 | D2: 0.2
A4: Фактор | B4: Доля от планового показателя при реализации сценария
A5: Загрузка оборудования | B5: 0.9 | C5: 1 | D5: 1.1
A6: Стоимость 1 часа игры | B6: 0.9 | C6: 1 | D6: 1.1
A7: Выручка бара на 1 час времени | B7: 0.9 | C7: 1 | D7: 1.1
A8: Сумма официальной з/п | B8: 1.1 | C8: 1 | D8: 0.9
A9: Ставка роста (g) | B9: 0.9 | C9: 1 | D9: 1.1
A11: Показатели финансовой эффективности
A12: Сценарий | B12: Пессимистичный | C12: Наиболее вероятный | D12: Оптимистичный
A13: NPV (с учетом TV) | B13: 20955627 | C13: 47456307 | D13: 80621347
A14: NPV (без учета TV) | B14: 3143031.4 | C14: 9979881.6 | D14: 17414032
A15: IRR (с учетом TV) | B15: 0.78941184 | C15: 1.2454181 | D15: 1.67752
A16: IRR (без учета TV) | B16: 0.38874834 | C16: 0.85579037 | D16: 1.3176681
A17: PP | B17: 29 | C17: 17 | D17: 13
A18: DPP | B18: 34 | C18: 19 | D18: 13
A19: PI с учетом TV | B19: 5.7852 | C19: 13.1012 | D19: 22.2569
A20: PI без учета TV | B20: 0.8677 | C20: 2.7551 | D20: 4.8075
A25: Ожидаемые:
A26: NPV (с учетом TV) | B26: =0.2*B13+0.6*C13+0.2*D13 -> 48789179
A27: NPV (без учета TV) | B27: =0.2*B14+0.6*C14+0.2*D14 -> 10099342
A28: Sigma (с учетом TV) | B28: =STDEV(B13:D13) -> 29894827
A29: Sigma (без учета TV) | B29: =STDEV(B14:D14) -> 7137583.4
