Workbook

Sheet Inputs
D2: Income Statement, MLN $
E3: Historical Results
C4: Revenue | E4: 2005 | F4: 2006 | G4: 2007 | J4: Tax rate | K4: 0.2
D5: Service revenue | E5: 2827 | F5: 3214.4 | G5: 3679.2
D6: Equipment sales | E6: 203.7 | F6: 258.7 | G6: 267 | J6: Cost of debt (rd) | K6: 0.055
D7: Total revenue | E7: 3030.8 | F7: 3473.2 | G7: 3946.3
J8: Risk free rate | K8: 0.0425
D9: System operating expenses | E9: 604.1 | F9: 639.7 | G9: 717.1
D10: Cost of equipment sold | E10: 511.9 | F10: 568.9 | G10: 640.2 | J10: Market risk premium | K10: 0.05
D11: Selling, general, administration costs | E11: 1217.7 | F11: 1399.6 | G11: 1555.6
D12: EBITDA | E12: =E7-E9-E10-E11 -> 697.1 | F12: =F7-F9-F10-F11 -> 865 | G12: =G7-G9-G10-G11 -> 1033.4 | J12: ba average | K12: =Сalculations!G75 -> 0.76828257
D14: Depreciation, amortization | E14: 490.1 | F14: 555.5 | G14: 582.3 | J14: Debt/Value average | K14: 0.281
D15: EBIT | E15: =E12-E14 -> 207 | F15: =F12-F14 -> 309.5 | G15: =G12-G14 -> 451.1
J16: re (D/E=0) WACC | K16: =Сalculations!E80 -> 0.080914128
D17: Interest expenses | E17: 84.9 | F17: 93.7 | G17: 84.7
D18: Equity in Earnings of Affiliates | E18: 66.7 | F18: 93.1 | G18: 90 | J18: WACC (D/V=average) | K18: =Сalculations!G81 -> 0.062780106
D19: Gain/Loss on investment | E19: 18.1 | F19: 50.8 | G19: 83.1
D20: Other Income | E20: 54.5 | F20: -46.6 | G20: 7
D21: EBT | E21: =E15-E17+E18+E19+E20 -> 261.4 | F21: =F15-F17+F18+F19+F20 -> 313.1 | G21: =G15-G17+G18+G19+G20 -> 546.5
D23: Tax | E23: =$K$4*E21 -> 52.28 | F23: =$K$4*F21 -> 62.62 | G23: =$K$4*G21 -> 109.3
D24: Net income | E24: =E21-E23 -> 209.12 | F24: =F21-F23 -> 250.48 | G24: =G21-G23 -> 437.2
D29: Balance Sheet, MLN$
E31: Historical Results
C32: Assets | E32: 2005 | F32: 2006 | G32: 2007
C33: Current Assets
D34: Cash | E34: 29 | F34: 32.9 | G34: 204.5
D35: Marketable securities | E35: 0 | F35: 249 | G35: 16.4
D36: Accounts receivable | E36: 362.4 | F36: 407.4 | G36: 435.5
D37: Inventory | E37: 92.7 | F37: 117.2 | G37: 101
D38: Prepaid expenses | E38: 32.1 | F38: 35 | G38: 41.6
D39: Deferred taxes | E39: 8.2 | F39: 0 | G39: 18.6
D40: Other current assets | E40: 15.5 | F40: 13.4 | G40: 16.2
D41: Total current assets | E41: =SUM(E34:E40) -> 539.9 | F41: =SUM(F34:F40) -> 854.9 | G41: =SUM(G34:G40) -> 833.8
C42: Fixed (Long-Term) Assets
D43: Property, plant, and equipment | E43: 2553 | F43: 2628.8 | G43: 2595.1
D44: Licenses | E44: 1362.3 | F44: 1494.3 | G44: 1482.4
D45: Customer lists | E45: 47.6 | F45: 26.2 | G45: 15.4
D46: Marketable equity securities | E46: 225.4 | F46: 4.9 | G46: 0
D47: Investment in affiliated entities | E47: 172.1 | F47: 150.3 | G47: 157.7
D48: Long-Term note receivable | E48: 4.7 | F48: 4.5 | G48: 4.4
...

Sheet Сalculations
A1: 0. | B1: Historical Results
B2: 2005 | C2: 2006 | D2: 2007
A3: CapEx | B3: - | C3: =Inputs!F43-Inputs!E43+Inputs!F14 -> 631.3 | D3: =Inputs!G43-Inputs!F43+Inputs!G14 -> 548.6 | F3: Capex=capital expenditures
A4: NWC | B4: =Inputs!E36+Inputs!E37+Inputs!E38-Inputs!E57-Inputs!E58-Inputs!E59 -> 78.8 | C4: =Inputs!F36+Inputs!F37+Inputs!F38-Inputs!F57-Inputs!F58-Inputs!F59 -> 133.6 | D4: =Inputs!G36+Inputs!G37+Inputs!G38-Inputs!G57-Inputs!G58-Inputs!G59 -> 114.7 | F4: chage NWC=change working capital
A5: Delta NWC | B5: - | C5: =C4-B4 -> 54.8 | D5: =D4-C4 -> -18.9 | F5: CapEx = PP&E (current period) – PP&E (prior period) + Depreciation (current period)
A6: EBITDA | B6: =Inputs!E12 -> 697.1 | C6: =Inputs!F12 -> 865 | D6: =Inputs!G12 -> 1033.4 | F6: NWC= (accunt recievable+inventory+prepaid expenses)-(accounts payable+deffered revenue deposits+accrued liabilities)
A7: EBIT | B7: =Inputs!E15 -> 207 | C7: =Inputs!F15 -> 309.5 | D7: =Inputs!G15 -> 451.1
A8: NOPAT | B8: =(1-Inputs!$K$4)*Сalculations!B7 -> 165.6 | C8: =(1-Inputs!$K$4)*Сalculations!C7 -> 247.6 | D8: =(1-Inputs!$K$4)*Сalculations!D7 -> 360.88 | F8: Delta NWC=WCt-WCt-1
A9: Unlevered FCF | B9: - | C9: =C8+Inputs!F14-C5-C3 -> 117 | D9: =D8+Inputs!G14-D5-D3 -> 413.48
F10: EBITDA=ser.rev+eq.rev.-sys.oper.exp-cost of eq.sold-selling,gen,adm exp
F11: EBIT=EBITDA-depr,amort
F12: NOPAT=(1-t)*EBIT
F13: UNLFCF=NOPAT+depr,amort-deltaNWC-CaPex
A16: 1. | B16: Operating Assumptions
B17: 2007
A18: Service revenue | B18: =Inputs!G5 -> 3679.2
A19: Equipment sales/Service revenue | B19: =Inputs!G6/Inputs!G5 -> 0.072570124
A20: System operating expenses/Service revenue | B20: =Inputs!G9/Inputs!G5 -> 0.1949065
A21: Equipment COGS (Cost of equipment sold/equipment sales) | B21: =Inputs!G10/Inputs!G6 -> 2.3977528
A22: SG&A/Total Revenue | B22: =Inputs!G11/Inputs!G7 -> 0.39419203
A23: Depreciation, amortization in CapEX | B23: =Inputs!G14/Сalculations!D3 -> 1.0614291
A24: Tax Rate | B24: =Inputs!K4 -> 0.2
A25: Working Capital Assumptions:
A26: Accounts Receivable (turnover) | B26: =Inputs!G36/((Inputs!$G$7)/360) -> 39.728353 | D26: turnover assets=Balance/(revenue/360)
A27: Days Sales Equip. Rev. (turnover) | B27: =Inputs!G37/((Inputs!$G$7)/360) -> 9.2136938 | D27: turnover liabilities=Balance/(cash operating expenditure/360)
A28: Prepaid Expenses (turnover) | B28: =Inputs!G38/((Inputs!$G$7)/360) -> 3.7949472 | D28: forcasted indicator= turnover*revenue or cost of sales/360
A29: Accounts Payable (turnover) | B29: =Inputs!G57/((Inputs!G9)/360) -> 130.92735
A30: Deferred Serv. Revenue (turnover) | B30: =Inputs!G58/((Inputs!G9)/360) -> 71.98996
A31: Accrued Liabilities (turnover) | B31: =Inputs!G59/((Inputs!G9)/360) -> 29.719704
A32: Cap-x/Total Revenue | B32: =D3/Inputs!G7 -> 0.13901629
A35: 2. | B35: Intermediate Operating Cash Flows
A36: Operating Results | B36: 2008 | C36: 2009 | D36: 2010 | E36: 2011 | F36: 2012
A37: Service Revenue | B37: =Inputs!G5*(1+Inputs!E88) -> 4194.288 | C37: =B37*(1+Inputs!F88) -> 4781.4883 | D37: =C37*(1+Inputs!G88) -> 5379.1744 | E37: =D37*(1+Inputs!H88) -> 5917.0918 | F37: =E37*(1+Inputs!I88) -> 6331.2882
A38: Plus: Equipment Sales | B38: =$B$19*B37 -> 304.38 | C38: =$B$19*C37 -> 346.9932 | D38: =$B$19*D37 -> 390.36735 | E38: =$B$19*E37 -> 429.40409 | F38: =$B$19*F37 -> 459.46237
A39: Total Revenue | B39: =B37+B38 -> 4498.668 | C39: =C37+C38 -> 5128.4815 | D39: =D37+D38 -> 5769.5417 | E39: =E37+E38 -> 6346.4959 | F39: =F37+F38 -> 6790.7506
A40: Less: System Operating Expenses | B40: =$B$20*B37 -> 817.494 | C40: =$B$20*C37 -> 931.94316 | D40: =$B$20*D37 -> 1048.4361 | E40: =$B$20*E37 -> 1153.2797 | F40: =$B$20*F37 -> 1234.0092
A41: Less: Cost of Equipment Sold | B41: =$B$21*B38 -> 729.828 | C41: =$B$21*C38 -> 832.00392 | D41: =$B$21*D38 -> 936.00441 | E41: =$B$21*E38 -> 1029.6049 | F41: =$B$21*F38 -> 1101.6772
A42: Less: Selling, General & Administrative | B42: =$B$22*B39 -> 1773.3391 | C42: =$B$22*C39 -> 2021.6065 | D42: =$B$22*D39 -> 2274.3073 | E42: =$B$22*E39 -> 2501.7381 | F42: =$B$22*F39 -> 2676.8597
A43: EBITDA | B43: =B39-B40-B41-B42 -> 1178.0069 | C43: =C39-C40-C41-C42 -> 1342.9279 | D43: =D39-D40-D41-D42 -> 1510.7939 | E43: =E39-E40-E41-E42 -> 1661.8733 | F43: =F39-F40-F41-F42 -> 1778.2044
A44: Less: Depreciation & Amortization | B44: =$B$23*B55 -> 668.50239 | C44: =$B$23*C55 -> 762.09273 | D44: =$B$23*D55 -> 918.59391 | E44: =$B$23*E55 -> 1030.6624 | F44: =$B$23*F55 -> 1117.2245
...

Sheet Results
C1: Income Statement, MLN $ | E1: Historical Results | H1: Forecast Period
C2: Revenue | E2: 2005 | F2: 2006 | G2: 2007 | H2: 2008 | I2: 2009 | J2: 2010 | K2: 2011 | L2: 2012
D3: Service revenue | E3: =Inputs!E5 -> 2827 | F3: =Inputs!F5 -> 3214.4 | G3: =Inputs!G5 -> 3679.2 | H3: =Сalculations!B37 -> 4194.288 | I3: =Сalculations!C37 -> 4781.4883 | J3: =Сalculations!D37 -> 5379.1744 | K3: =Сalculations!E37 -> 5917.0918 | L3: =Сalculations!F37 -> 6331.2882
D4: Equipment sales | E4: =Inputs!E6 -> 203.7 | F4: =Inputs!F6 -> 258.7 | G4: =Inputs!G6 -> 267 | H4: =Сalculations!B38 -> 304.38 | I4: =Сalculations!C38 -> 346.9932 | J4: =Сalculations!D38 -> 390.36735 | K4: =Сalculations!E38 -> 429.40409 | L4: =Сalculations!F38 -> 459.46237
D5: Total Revenue | E5: =E3+E4 -> 3030.7 | F5: =F3+F4 -> 3473.1 | G5: =G3+G4 -> 3946.2 | H5: =Сalculations!B39 -> 4498.668 | I5: =Сalculations!C39 -> 5128.4815 | J5: =Сalculations!D39 -> 5769.5417 | K5: =Сalculations!E39 -> 6346.4959 | L5: =Сalculations!F39 -> 6790.7506
D7: System operating expenses | E7: =Inputs!E9 -> 604.1 | F7: =Inputs!F9 -> 639.7 | G7: =Inputs!G9 -> 717.1 | H7: =Сalculations!B40 -> 817.494 | I7: =Сalculations!C40 -> 931.94316 | J7: =Сalculations!D40 -> 1048.4361 | K7: =Сalculations!E40 -> 1153.2797 | L7: =Сalculations!F40 -> 1234.0092
D8: Cost of equipment sold | E8: =Inputs!E10 -> 511.9 | F8: =Inputs!F10 -> 568.9 | G8: =Inputs!G10 -> 640.2 | H8: =Сalculations!B41 -> 729.828 | I8: =Сalculations!C41 -> 832.00392 | J8: =Сalculations!D41 -> 936.00441 | K8: =Сalculations!E41 -> 1029.6049 | L8: =Сalculations!F41 -> 1101.6772
D9: Selling, general, administration costs | E9: =Inputs!E11 -> 1217.7 | F9: =Inputs!F11 -> 1399.6 | G9: =Inputs!G11 -> 1555.6 | H9: =Сalculations!B42 -> 1773.3391 | I9: =Сalculations!C42 -> 2021.6065 | J9: =Сalculations!D42 -> 2274.3073 | K9: =Сalculations!E42 -> 2501.7381 | L9: =Сalculations!F42 -> 2676.8597
D10: EBITDA | E10: =Inputs!E12 -> 697.1 | F10: =Inputs!F12 -> 865 | G10: =Inputs!G12 -> 1033.4 | H10: =Сalculations!B43 -> 1178.0069 | I10: =Сalculations!C43 -> 1342.9279 | J10: =Сalculations!D43 -> 1510.7939 | K10: =Сalculations!E43 -> 1661.8733 | L10: =Сalculations!F43 -> 1778.2044
D12: Depreciation, amortization | E12: =Inputs!E14 -> 490.1 | F12: =Inputs!F14 -> 555.5 | G12: =Inputs!G14 -> 582.3 | H12: =Сalculations!B44 -> 668.50239 | I12: =Сalculations!C44 -> 762.09273 | J12: =Сalculations!D44 -> 918.59391 | K12: =Сalculations!E44 -> 1030.6624 | L12: =Сalculations!F44 -> 1117.2245
D13: EBIT | E13: =Inputs!E15 -> 207 | F13: =Inputs!F15 -> 309.5 | G13: =Inputs!G15 -> 451.1 | H13: =Сalculations!C138 -> 514.2 | I13: =Сalculations!D138 -> 586.2 | J13: =Сalculations!E138 -> 598.6 | K13: =Сalculations!F138 -> 638.4 | L13: =Сalculations!G138 -> 668.8
D15: Interest expenditures | E15: =Inputs!E17 -> 84.9 | F15: =Inputs!F17 -> 93.7 | G15: =Inputs!G17 -> 84.7 | H15: =Сalculations!C139 -> 199 | I15: =Сalculations!D139 -> 184 | J15: =Сalculations!E139 -> 165 | K15: =Сalculations!F139 -> 148 | L15: =Сalculations!G139 -> 127
D16: Equity in Earnings of Affiliates | E16: =Inputs!E18 -> 66.7 | F16: =Inputs!F18 -> 93.1 | G16: =Inputs!G18 -> 90 | H16: =Сalculations!C140 -> 0 | I16: =Сalculations!D140 -> 0 | J16: =Сalculations!E140 -> 0 | K16: =Сalculations!F140 -> 0 | L16: =Сalculations!G140 -> 0
D17: Gain/Loss on investment | E17: =Inputs!E19 -> 18.1 | F17: =Inputs!F19 -> 50.8 | G17: =Inputs!G19 -> 83.1 | H17: =Сalculations!C141 -> 0 | I17: =Сalculations!D141 -> 0 | J17: =Сalculations!E141 -> 0 | K17: =Сalculations!F141 -> 0 | L17: =Сalculations!G141 -> 0
D18: Other Income | E18: =Inputs!E20 -> 54.5 | F18: =Inputs!F20 -> -46.6 | G18: =Inputs!G20 -> 7 | H18: =Сalculations!C142 -> 0 | I18: =Сalculations!D142 -> 0 | J18: =Сalculations!E142 -> 0 | K18: =Сalculations!F142 -> 0 | L18: =Сalculations!G142 -> 0
D19: EBT | E19: =Inputs!E21 -> 261.4 | F19: =Inputs!F21 -> 313.1 | G19: =Inputs!G21 -> 546.5 | H19: =Сalculations!C143 -> 315.2 | I19: =Сalculations!D143 -> 402.2 | J19: =Сalculations!E143 -> 433.6 | K19: =Сalculations!F143 -> 490.4 | L19: =Сalculations!G143 -> 541.8
D21: Tax | E21: =Inputs!E23 -> 52.28 | F21: =Inputs!F23 -> 62.62 | G21: =Inputs!G23 -> 109.3 | H21: =Сalculations!C144 -> 63.04 | I21: =Сalculations!D144 -> 80.44 | J21: =Сalculations!E144 -> 86.72 | K21: =Сalculations!F144 -> 98.08 | L21: =Сalculations!G144 -> 108.36
D22: Net income | E22: =Inputs!E24 -> 209.12 | F22: =Inputs!F24 -> 250.48 | G22: =Inputs!G24 -> 437.2 | H22: =Сalculations!C145 -> 252.16 | I22: =Сalculations!D145 -> 321.76 | J22: =Сalculations!E145 -> 346.88 | K22: =Сalculations!F145 -> 392.32 | L22: =Сalculations!G145 -> 433.44
D24: NOPAT | E24: =Сalculations!B8 -> 165.6 | F24: =Сalculations!C8 -> 247.6 | G24: =Сalculations!D8 -> 360.88 | H24: =Сalculations!B47 -> 407.60364 | I24: =Сalculations!C47 -> 464.66815 | J24: =Сalculations!D47 -> 473.75999 | K24: =Сalculations!E47 -> 504.96873 | L24: =Сalculations!F47 -> 528.7839
D25: CapEx | E25: =Сalculations!B3 -> - | F25: =Сalculations!C3 -> 631.3 | G25: =Сalculations!D3 -> 548.6 | H25: =Сalculations!B55 -> 629.81352 | I25: =Сalculations!C55 -> 717.98741 | J25: =Сalculations!D55 -> 865.43126 | K25: =Сalculations!E55 -> 971.01387 | L25: =Сalculations!F55 -> 1052.5663
D26: Delta NWC | E26: =Сalculations!B5 -> - | F26: =Сalculations!C5 -> 54.8 | G26: =Сalculations!D5 -> -18.9 | H26: =Сalculations!B63 -> 16.0413 | I26: =Сalculations!C63 -> 18.303782 | J26: =Сalculations!D63 -> 18.630635 | K26: =Сalculations!E63 -> 16.767572 | L26: =Сalculations!F63 -> 12.91103
D27: Unlevered FCF | E27: - | F27: =Сalculations!C9 -> 117 | G27: =Сalculations!D9 -> 413.48 | H27: =Сalculations!B51 -> 430.25121 | I27: =Сalculations!C51 -> 490.46968 | J27: =Сalculations!D51 -> 508.29201 | K27: =Сalculations!E51 -> 547.84966 | L27: =Сalculations!F51 -> 580.53107
C30: Balance Sheet, MLN$
E31: Historical Results | H31: Forecast Period
C32: Assets | E32: 2005 | F32: 2006 | G32: 2007 | H32: 2008 | I32: 2009 | J32: 2010 | K32: 2011 | L32: 2012
C33: Current Assets
D34: Cash | E34: =Inputs!E34 -> 29 | F34: =Inputs!F34 -> 32.9 | G34: =Inputs!G34 -> 204.5 | H34: =Сalculations!D152 -> 181.6 | I34: =Сalculations!E152 -> 215.8 | J34: =Сalculations!F152 -> 263.8 | K34: =Сalculations!G152 -> 347.8 | L34: =Сalculations!H152 -> -1674.8
D35: Marketable securities | E35: =Inputs!E35 -> 0 | F35: =Inputs!F35 -> 249 | G35: =Inputs!G35 -> 16.4 | H35: =Сalculations!D153 -> 16.4 | I35: =Сalculations!E153 -> 16.4 | J35: =Сalculations!F153 -> 16.4 | K35: =Сalculations!G153 -> 16.4 | L35: =Сalculations!H153 -> 16.4
D36: Accounts receivable | E36: =Inputs!E36 -> 362.4 | F36: =Inputs!F36 -> 407.4 | G36: =Inputs!G36 -> 435.5 | H36: =Сalculations!D154 -> 496.5 | I36: =Сalculations!E154 -> 566 | J36: =Сalculations!F154 -> 636.7 | K36: =Сalculations!G154 -> 700.4 | L36: =Сalculations!H154 -> 749.4
D37: Inventory | E37: =Inputs!E37 -> 92.7 | F37: =Inputs!F37 -> 117.2 | G37: =Inputs!G37 -> 101 | H37: =Сalculations!D155 -> 115.1 | I37: =Сalculations!E155 -> 131.3 | J37: =Сalculations!F155 -> 147.7 | K37: =Сalculations!G155 -> 162.4 | L37: =Сalculations!H155 -> 173.8
D38: Prepaid expenses | E38: =Inputs!E38 -> 32.1 | F38: =Inputs!F38 -> 35 | G38: =Inputs!G38 -> 41.6 | H38: =Сalculations!D156 -> 47.4 | I38: =Сalculations!E156 -> 54.1 | J38: =Сalculations!F156 -> 60.8 | K38: =Сalculations!G156 -> 66.9 | L38: =Сalculations!H156 -> 71.6
D39: Deferred taxes | E39: =Inputs!E39 -> 8.2 | F39: =Inputs!F39 -> 0 | G39: =Inputs!G39 -> 18.6 | H39: =Сalculations!D157 -> 18.6 | I39: =Сalculations!E157 -> 18.6 | J39: =Сalculations!F157 -> 18.6 | K39: =Сalculations!G157 -> 18.6 | L39: =Сalculations!H157 -> 18.6
D40: Other current assets | E40: =Inputs!E40 -> 15.5 | F40: =Inputs!F40 -> 13.4 | G40: =Inputs!G40 -> 16.2 | H40: =Сalculations!D158 -> 16.2 | I40: =Сalculations!E158 -> 16.2 | J40: =Сalculations!F158 -> 16.2 | K40: =Сalculations!G158 -> 16.2 | L40: =Сalculations!H158 -> 16.2
D41: Total current assets | E41: 539.9 | F41: 854.9 | G41: 833.8 | H41: =SUM(H34:H40) -> 891.8 | I41: =SUM(I34:I40) -> 1018.4 | J41: =SUM(J34:J40) -> 1160.2 | K41: =SUM(K34:K40) -> 1328.7 | L41: =SUM(L34:L40) -> -628.8
C43: Fixed (Long-Term) Assets
D44: Property, plant, and equipment | E44: =Inputs!E43 -> 2553 | F44: =Inputs!F43 -> 2628.8 | G44: =Inputs!G43 -> 2595.1 | H44: =Сalculations!D161 -> 2556.4111 | I44: =Сalculations!E161 -> 2512.3058 | J44: =Сalculations!F161 -> 2459.1432 | K44: =Сalculations!G161 -> 2399.4947 | L44: =Сalculations!H161 -> 2334.8365
D45: Licenses | E45: =Inputs!E44 -> 1362.3 | F45: =Inputs!F44 -> 1494.3 | G45: =Inputs!G44 -> 1482.4 | H45: =Сalculations!D162 -> 1482.4 | I45: =Сalculations!E162 -> 1482.4 | J45: =Сalculations!F162 -> 1482.4 | K45: =Сalculations!G162 -> 1482.4 | L45: =Сalculations!H162 -> 1482.4
D46: Customer lists | E46: =Inputs!E45 -> 47.6 | F46: =Inputs!F45 -> 26.2 | G46: =Inputs!G45 -> 15.4 | H46: =Сalculations!D163 -> 15.4 | I46: =Сalculations!E163 -> 15.4 | J46: =Сalculations!F163 -> 15.4 | K46: =Сalculations!G163 -> 15.4 | L46: =Сalculations!H163 -> 15.4
D47: Marketable equity securities | E47: =Inputs!E46 -> 225.4 | F47: =Inputs!F46 -> 4.9 | G47: =Inputs!G46 -> 0 | H47: =Сalculations!D164 -> 0 | I47: =Сalculations!E164 -> 0 | J47: =Сalculations!F164 -> 0 | K47: =Сalculations!G164 -> 0 | L47: =Сalculations!H164 -> 0
D48: Investment in affiliated entities | E48: =Inputs!E47 -> 172.1 | F48: =Inputs!F47 -> 150.3 | G48: =Inputs!G47 -> 157.7 | H48: =Сalculations!D165 -> 157.7 | I48: =Сalculations!E165 -> 157.7 | J48: =Сalculations!F165 -> 157.7 | K48: =Сalculations!G165 -> 157.7 | L48: =Сalculations!H165 -> 157.7
...
