Workbook

Sheet BS
A1: Баланс МСФО, тыс.руб.
A2: Наименование показателя | B2: 41274 | C2: 41639 | D2: 42004 | E2: 42369 | F2: 42735 | G2: 43100 | H2: 43465 | I2: 43830 | J2: 44196
A3: АКТИВЫ
A4: Оборотные активы
A5: Денежные средства и их эквиваленты | B5: 299000000 | C5: 275000000 | D5: 216000000 | E5: 559000000 | F5: 790000000 | G5: 322000000 | H5: 832000000 | I5: 228000000 | J5: 806000000
A6: Денежные средства с ограничением к использованию | B6: 4000000 | C6: 1000000 | D6: 1000000 | E6: 2000000 | F6: 2000000 | G6: 13000000 | H6: 12000000 | I6: 10000000 | J6: 17000000
A7: Прочие оборотные финансовые активы | B7: 90000000 | C7: 232000000 | D7: 723000000 | E7: 986000000 | F7: 447000000 | G7: 336000000 | H7: 633000000 | I7: 501000000 | J7: 817000000
A8: Дебиторская задолженность | B8: 237000000 | C8: 415000000 | D8: 554000000 | E8: 367000000 | F8: 485000000 | G8: 843000000 | H8: 642000000 | I8: 620000000 | J8: 468000000
A9: Банковские кредиты выданные | B9: - | C9: - | D9: - | E9: - | F9: - | G9: - | H9: - | I9: 130000000 | J9: 131000000
A10: Товарно-материальные запасы | B10: 134000000 | C10: 202000000 | D10: 233000000 | E10: 219000000 | F10: 283000000 | G10: 324000000 | H10: 393000000 | I10: 438000000 | J10: 361000000
A11: Авансы выданные и прочие оборотные активы | B11: 185000000 | C11: 330000000 | D11: 404000000 | E11: 271000000 | F11: 293000000 | G11: 454000000 | H11: 510000000 | I11: 469000000 | J11: 322000000
A12: Итого оборотные активы | B12: 949000000 | C12: 1455000000 | D12: 2131000000 | E12: 2404000000 | F12: 2300000000 | G12: 2292000000 | H12: 3022000000 | I12: 2396000000 | J12: =SUM(J5:J11) -> 2922000000
A13: Внеоборотные активы
A14: Основные средства | B14: 2629000000 | C14: 5330000000 | D14: 5666000000 | E14: 5891000000 | F14: 7090000000 | G14: 7923000000 | H14: 8445000000 | I14: 8706000000 | J14: 10401000000
A15: Активы в форме права пользования | B15: - | C15: - | D15: - | E15: - | F15: - | G15: - | H15: - | I15: 160000000 | J15: 155000000
A16: Нематериальные активы | B16: 19000000 | C16: 37000000 | D16: 49000000 | E16: 48000000 | F16: 59000000 | G16: 75000000 | H16: 75000000 | I16: 66000000 | J16: 80000000
A17: Прочие внеоборотные активы | B17: 24000000 | C17: 40000000 | D17: 281000000 | E17: 510000000 | F17: 808000000 | G17: 606000000 | H17: 239000000 | I17: 229000000 | J17: 275000000
A18: Инвестиции в совместные и ассоциированные предприятия | B18: 186000000 | C18: 327000000 | D18: 347000000 | E18: 353000000 | F18: 411000000 | G18: 635000000 | H18: 735000000 | I18: 801000000 | J18: 846000000
A19: Банковские кредиты выданные | B19: 13000000 | C19: 12000000 | D19: 14000000 | E19: 18000000 | F19: 26000000 | G19: 121000000 | H19: 239000000 | I19: 291000000 | J19: 363000000
A20: Отложенные налоговые активы | B20: 4000000 | C20: 14000000 | D20: 24000000 | E20: 25000000 | F20: 22000000 | G20: 26000000 | H20: 28000000 | I20: 33000000 | J20: 54000000
A21: Гудвилл | B21: 144000000 | C21: 164000000 | D21: 215000000 | E21: 230000000 | F21: 230000000 | G21: 265000000 | H21: 85000000 | I21: 93000000 | J21: 82000000
A22: Прочие внеоборотные нефинансовые активы | B22: 3000000 | C22: 12000000 | D22: 9000000 | E22: 8000000 | F22: 84000000 | G22: 285000000 | H22: 295000000 | I22: 171000000 | J22: 172000000
A23: Итого внеоборотные активы | B23: 3022000000 | C23: 5936000000 | D23: 6605000000 | E23: 7083000000 | F23: 8730000000 | G23: 9936000000 | H23: 10141000000 | I23: 10550000000 | J23: =SUM(J14:J22) -> 12428000000
A24: Активы, предназначенные для продажи | B24: 0 | C24: 147000000 | D24: 0 | E24: 150000000 | F24: 0 | G24: 0 | H24: 0 | I24: 0 | J24: 0
A25: Итого активы | B25: 3971000000 | C25: 7538000000 | D25: 8736000000 | E25: 9637000000 | F25: 11030000000 | G25: 12228000000 | H25: 13163000000 | I25: 12946000000 | J25: =J23+J12 -> 15350000000
A26: ОБЯЗАТЕЛЬСТВА И КАПИТАЛ
A27: Краткосрочные обязательства
A28: Кредиторская задолженность и начисления | B28: 211000000 | C28: 488000000 | D28: 494000000 | E28: 476000000 | F28: 583000000 | G28: 971000000 | H28: 1130000000 | I28: 1162000000 | J28: 1546000000
A29: Кредиты и займы | B29: 143000000 | C29: 684000000 | D29: 1216000000 | E29: 1040000000 | F29: 1671000000 | G29: 2229000000 | H29: 978000000 | I29: 795000000 | J29: 798000000
A30: Обязательства по налогу на прибыль | B30: 7000000 | C30: 11000000 | D30: 39000000 | E30: 8000000 | F30: 6000000 | G30: 39000000 | H30: 23000000 | I30: 23000000 | J30: 14000000
A31: Обязательства по прочим налогам | B31: 83000000 | C31: 161000000 | D31: 162000000 | E31: 138000000 | F31: 222000000 | G31: 278000000 | H31: 327000000 | I31: 379000000 | J31: 301000000
A32: Резервы | B32: 5000000 | C32: 22000000 | D32: 36000000 | E32: 28000000 | F32: 29000000 | G32: 29000000 | H32: 43000000 | I32: 55000000 | J32: 68000000
A33: Предоплата по договорам поставки нефти | B33: - | C33: - | D33: - | E33: - | F33: - | G33: 264000000 | H33: 354000000 | I33: 332000000 | J33: 357000000
A34: Прочие краткосрочные обязательства | B34: 1000000 | C34: 11000000 | D34: 123000000 | E34: 127000000 | F34: 262000000 | G34: 26000000 | H34: 19000000 | I34: 9000000 | J34: 8000000
A35: Итого краткосрочные обязательства | B35: 453000000 | C35: 1387000000 | D35: 2031000000 | E35: 1817000000 | F35: 2773000000 | G35: 3836000000 | H35: 2874000000 | I35: 2755000000 | J35: =SUM(J28:J34) -> 3092000000
A36: Долгосрочные обязательства
A37: Кредиты и займы | B37: 837000000 | C37: 1676000000 | D37: 2190000000 | E37: 2283000000 | F37: 1914000000 | G37: 1783000000 | H37: 3413000000 | I37: 3033000000 | J37: 3810000000
A38: Отложенные налоговые обязательства | B38: 264000000 | C38: 660000000 | D38: 594000000 | E38: 578000000 | F38: 785000000 | G38: 814000000 | H38: 837000000 | I38: 844000000 | J38: 1072000000
A39: Резервы | B39: 71000000 | C39: 116000000 | D39: 107000000 | E39: 143000000 | F39: 203000000 | G39: 245000000 | H39: 244000000 | I39: 343000000 | J39: 437000000
A40: Предоплата по договорам поставки нефти | B40: 0 | C40: 470000000 | D40: 887000000 | E40: 1785000000 | F40: 1586000000 | G40: 1322000000 | H40: 1072000000 | I40: 750000000 | J40: 1401000000
...

Sheet IS
A1: Отчет о прибылях и убытках МСФО, тыс.руб.
A2: Наименование показателя | B2: 2012 | C2: 2013 | D2: 2014 | E2: 2015 | F2: 2016 | G2: 2017 | H2: 2018 | I2: 2019 | J2: 2020 | L2: 2012 | M2: 2013 | N2: 2014 | O2: 2015 | P2: 2016 | Q2: 2017 | R2: 2018 | S2: 2019 | T2: 2020 | Z2: 1526000000 | AA2: 2428000000 | AB2: 2992000000
A3: Реализация нефти и газа, нефтепродуктов и нефтехимии | B3: =Z2+Z3 -> 3024000000 | C3: =AA2+AA3 -> 4624000000 | D3: =AB2+AB3 -> 5440000000 | E3: 5071000000 | F3: 4887000000 | G3: 5877000000 | H3: 8076000000 | I3: 8490000000 | J3: 5628000000 | L3: - | M3: =C3/B3-1 -> 0.52910053 | N3: =D3/C3-1 -> 0.17647059 | O3: =E3/D3-1 -> -0.067830882 | P3: =F3/E3-1 -> -0.036284756 | Q3: =G3/F3-1 -> 0.20257827 | R3: =H3/G3-1 -> 0.3741705 | S3: =I3/H3-1 -> 0.051263001 | T3: =J3/I3-1 -> -0.33710247 | W3: срарифм | X3: =AVERAGE(M6:S6) -> 0.17499941 | Z3: 1498000000 | AA3: 2196000000 | AB3: 2448000000
A4: Вспомогательные услуги и прочая реализация | B4: 42000000 | C4: 58000000 | D4: 75000000 | E4: 70000000 | F4: 75000000 | G4: 77000000 | H4: 80000000 | I4: 86000000 | J4: 77000000 | L4: - | M4: =C4/B4-1 -> 0.38095238 | N4: =D4/C4-1 -> 0.29310345 | O4: =E4/D4-1 -> -0.066666667 | P4: =F4/E4-1 -> 0.071428571 | Q4: =G4/F4-1 -> 0.026666667 | R4: =H4/G4-1 -> 0.038961039 | S4: =I4/H4-1 -> 0.075 | T4: =J4/I4-1 -> -0.10465116 | W4: cagr | X4: =(I6/B6)^(1/8)-1 -> 0.13779155
A5: Доход от совместных и ассоциированных предприятий | B5: 23000000 | C5: 12000000 | D5: -12000000 | E5: 9000000 | F5: 26000000 | G5: 60000000 | H5: 82000000 | I5: 100000000 | J5: 52000000 | L5: - | M5: =C5/B5-1 -> -0.47826087 | N5: =D5/C5-1 -> -2 | O5: =E5/D5-1 -> -1.75 | P5: =F5/E5-1 -> 1.8888889 | Q5: =G5/F5-1 -> 1.3076923 | R5: =H5/G5-1 -> 0.36666667 | S5: =I5/H5-1 -> 0.2195122 | T5: =J5/I5-1 -> -0.48
A6: Итого выручка от реализации и доход от совместных и ассоциированных предприятий | B6: 3089000000 | C6: 4694000000 | D6: 5503000000 | E6: 5150000000 | F6: 4988000000 | G6: 6014000000 | H6: 8238000000 | I6: 8676000000 | J6: 5757000000 | L6: - | M6: =C6/B6-1 -> 0.51958563 | N6: =D6/C6-1 -> 0.17234768 | O6: =E6/D6-1 -> -0.064146829 | P6: =F6/E6-1 -> -0.031456311 | Q6: =G6/F6-1 -> 0.20569366 | R6: =H6/G6-1 -> 0.36980379 | S6: =I6/H6-1 -> 0.053168245 | T6: =J6/I6-1 -> -0.33644537
A7: Затраты и расходы
A8: Производственные и операционные расходы | B8: -247000000 | C8: -389000000 | D8: -469000000 | E8: -575000000 | F8: -559000000 | G8: -607000000 | H8: -642000000 | I8: -715000000 | J8: -767000000 | L8: - | M8: =C8/B8-1 -> 0.57489879 | N8: =D8/C8-1 -> 0.20565553 | O8: =E8/D8-1 -> 0.22601279 | P8: =F8/E8-1 -> -0.027826087 | Q8: =G8/F8-1 -> 0.085867621 | R8: =H8/G8-1 -> 0.057660626 | S8: =I8/H8-1 -> 0.11370717 | T8: =J8/I8-1 -> 0.072727273
A9: Стоимость приобретенной нефти, газа, нефтепродуктов и услуг по переработке нефти | B9: -319000000 | C9: -432000000 | D9: -495000000 | E9: -530000000 | F9: -614000000 | G9: -837000000 | H9: -1099000000 | I9: -1566000000 | J9: -691000000 | L9: - | M9: =C9/B9-1 -> 0.35423197 | N9: =D9/C9-1 -> 0.14583333 | O9: =E9/D9-1 -> 0.070707071 | P9: =F9/E9-1 -> 0.15849057 | Q9: =G9/F9-1 -> 0.36319218 | R9: =H9/G9-1 -> 0.3130227 | S9: =I9/H9-1 -> 0.42493176 | T9: =J9/I9-1 -> -0.5587484
A10: Общехозяйственные и административные расходы | B10: -68000000 | C10: -111000000 | D10: -114000000 | E10: -130000000 | F10: -129000000 | G10: -172000000 | H10: -167000000 | I10: -200000000 | J10: -127000000 | L10: - | M10: =C10/B10-1 -> 0.63235294 | N10: =D10/C10-1 -> 0.027027027 | O10: =E10/D10-1 -> 0.14035088 | P10: =F10/E10-1 -> -0.0076923077 | Q10: =G10/F10-1 -> 0.33333333 | R10: =H10/G10-1 -> -0.029069767 | S10: =I10/H10-1 -> 0.19760479 | T10: =J10/I10-1 -> -0.365
A11: Тарифы за пользование нефтепроводом и расходы на транспортировку | B11: -241000000 | C11: -392000000 | D11: -471000000 | E11: -542000000 | F11: -575000000 | G11: -596000000 | H11: -638000000 | I11: -733000000 | J11: -661000000 | L11: - | M11: =C11/B11-1 -> 0.62655602 | N11: =D11/C11-1 -> 0.20153061 | O11: =E11/D11-1 -> 0.1507431 | P11: =F11/E11-1 -> 0.060885609 | Q11: =G11/F11-1 -> 0.036521739 | R11: =H11/G11-1 -> 0.070469799 | S11: =I11/H11-1 -> 0.14890282 | T11: =J11/I11-1 -> -0.098226467
A12: Затраты, связанные с разведкой запасов нефти и газа | B12: -23000000 | C12: -17000000 | D12: -19000000 | E12: -13000000 | F12: -14000000 | G12: -15000000 | H12: -11000000 | I12: -11000000 | J12: -15000000 | L12: - | M12: =C12/B12-1 -> -0.26086957 | N12: =D12/C12-1 -> 0.11764706 | O12: =E12/D12-1 -> -0.31578947 | P12: =F12/E12-1 -> 0.076923077 | Q12: =G12/F12-1 -> 0.071428571 | R12: =H12/G12-1 -> -0.26666667 | S12: =I12/H12-1 -> 0 | T12: =J12/I12-1 -> 0.36363636
A13: Износ, истощение и амортизация | B13: -206000000 | C13: -392000000 | D13: -464000000 | E13: -450000000 | F13: -482000000 | G13: -586000000 | H13: -635000000 | I13: -687000000 | J13: -663000000 | L13: - | M13: =C13/B13-1 -> 0.90291262 | N13: =D13/C13-1 -> 0.18367347 | O13: =E13/D13-1 -> -0.030172414 | P13: =F13/E13-1 -> 0.071111111 | Q13: =G13/F13-1 -> 0.21576763 | R13: =H13/G13-1 -> 0.083617747 | S13: =I13/H13-1 -> 0.081889764 | T13: =J13/I13-1 -> -0.034934498
A14: Налоги, кроме налога на прибыль | B14: -672000000 | C14: -1024000000 | D14: -1195000000 | E14: -1277000000 | F14: -1296000000 | G14: -1919000000 | H14: -2701000000 | I14: -2666000000 | J14: -2121000000 | L14: - | M14: =C14/B14-1 -> 0.52380952 | N14: =D14/C14-1 -> 0.16699219 | O14: =E14/D14-1 -> 0.068619247 | P14: =F14/E14-1 -> 0.014878622 | Q14: =G14/F14-1 -> 0.48070988 | R14: =H14/G14-1 -> 0.40750391 | S14: =I14/H14-1 -> -0.012958164 | T14: =J14/I14-1 -> -0.20442611
A15: Экспортная пошлина | B15: -901000000 | C15: -1382000000 | D15: -1683000000 | E15: -925000000 | F15: -657000000 | G15: -658000000 | H15: -1061000000 | I15: -793000000 | J15: -334000000 | L15: - | M15: =C15/B15-1 -> 0.53385128 | N15: =D15/C15-1 -> 0.21780029 | O15: =E15/D15-1 -> -0.45038622 | P15: =F15/E15-1 -> -0.28972973 | Q15: =G15/F15-1 -> 0.00152207 | R15: =H15/G15-1 -> 0.61246201 | S15: =I15/H15-1 -> -0.25259189 | T15: =J15/I15-1 -> -0.57881463
A16: Итого затраты и расходы | B16: -2677000000 | C16: -4139000000 | D16: -4910000000 | E16: -4442000000 | F16: -4326000000 | G16: -5390000000 | H16: -6954000000 | I16: -7371000000 | J16: -5379000000 | L16: - | M16: =C16/B16-1 -> 0.54613373 | N16: =D16/C16-1 -> 0.18627688 | O16: =E16/D16-1 -> -0.095315682 | P16: =F16/E16-1 -> -0.026114363 | Q16: =G16/F16-1 -> 0.24595469 | R16: =H16/G16-1 -> 0.29016698 | S16: =I16/H16-1 -> 0.059965487 | T16: =J16/I16-1 -> -0.27024827
A17: Операционная прибыль | B17: 412000000 | C17: 555000000 | D17: 593000000 | E17: 708000000 | F17: 662000000 | G17: 624000000 | H17: 1284000000 | I17: 1305000000 | J17: 378000000 | L17: - | M17: =C17/B17-1 -> 0.34708738 | N17: =D17/C17-1 -> 0.068468468 | O17: =E17/D17-1 -> 0.19392917 | P17: =F17/E17-1 -> -0.064971751 | Q17: =G17/F17-1 -> -0.057401813 | R17: =H17/G17-1 -> 1.0576923 | S17: =I17/H17-1 -> 0.01635514 | T17: =J17/I17-1 -> -0.71034483
A18: Финансовые доходы | B18: 24000000 | C18: 21000000 | D18: 30000000 | E18: 55000000 | F18: 91000000 | G18: 107000000 | H18: 122000000 | I18: 143000000 | J18: 95000000 | L18: - | M18: =C18/B18-1 -> -0.125 | N18: =D18/C18-1 -> 0.42857143 | O18: =E18/D18-1 -> 0.83333333 | P18: =F18/E18-1 -> 0.65454545 | Q18: =G18/F18-1 -> 0.17582418 | R18: =H18/G18-1 -> 0.14018692 | S18: =I18/H18-1 -> 0.17213115 | T18: =J18/I18-1 -> -0.33566434
A19: Финансовые расходы | B19: -15000000 | C19: -56000000 | D19: -219000000 | E19: -269000000 | F19: -193000000 | G19: -225000000 | H19: -290000000 | I19: -227000000 | J19: -220000000 | L19: - | M19: =C19/B19-1 -> 2.7333333 | N19: =D19/C19-1 -> 2.9107143 | O19: =E19/D19-1 -> 0.2283105 | P19: =F19/E19-1 -> -0.28252788 | Q19: =G19/F19-1 -> 0.16580311 | R19: =H19/G19-1 -> 0.28888889 | S19: =I19/H19-1 -> -0.21724138 | T19: =J19/I19-1 -> -0.030837004
... A22: Курсовые разницы | B22: 11000000 | C22: -71000000 | D22: 64000000 | E22: 86000000 | F22: -70000000 | G22: 3000000 | H22: 107000000 | I22: 64000000 | J22: -163000000 | L22: - | M22: =C22/B22-1 -> -7.4545455 | N22: =D22/C22-1 -> -1.9014085 | O22: =E22/D22-1 -> 0.34375 | P22: =F22/E22-1 -> -1.8139535 | Q22: =G22/F22-1 -> -1.0428571 | R22: =H22/G22-1 -> 34.666667 | S22: =I22/H22-1 -> -0.40186916 | T22: =J22/I22-1 -> -3.546875
A23: Реализованные курсовые разницы по инструментам управления курсовым риском | B23: - | C23: - | D23: - | E23: -123000000 | F23: -147000000 | G23: -146000000 | H23: -146000000 | I23: -146000000 | J23: 2000000 | L23: - | M23: - | N23: - | O23: - | P23: =F23/E23-1 -> 0.19512195 | Q23: =G23/F23-1 -> -0.0068027211 | R23: =H23/G23-1 -> 0 | S23: =I23/H23-1 -> 0 | T23: =J23/I23-1 -> -1.0136986
A24: Прибыль до налогообложения | B24: 469000000 | C24: 632000000 | D24: 478000000 | E24: 460000000 | F24: 317000000 | G24: 395000000 | H24: 832000000 | I24: 994000000 | J24: 162000000 | L24: - | M24: =C24/B24-1 -> 0.34754797 | N24: =D24/C24-1 -> -0.24367089 | O24: =E24/D24-1 -> -0.037656904 | P24: =F24/E24-1 -> -0.31086957 | Q24: =G24/F24-1 -> 0.24605678 | R24: =H24/G24-1 -> 1.1063291 | S24: =I24/H24-1 -> 0.19471154 | T24: =J24/I24-1 -> -0.83702213
A25: Налог на прибыль | B25: -104000000 | C25: -81000000 | D25: -128000000 | E25: -104000000 | F25: -116000000 | G25: -98000000 | H25: -183000000 | I25: -192000000 | J25: 19000000 | L25: - | M25: =C25/B25-1 -> -0.22115385 | N25: =D25/C25-1 -> 0.58024691 | O25: =E25/D25-1 -> -0.1875 | P25: =F25/E25-1 -> 0.11538462 | Q25: =G25/F25-1 -> -0.15517241 | R25: =H25/G25-1 -> 0.86734694 | S25: =I25/H25-1 -> 0.049180328 | T25: =J25/I25-1 -> -1.0989583
A26: Чистая прибыль | B26: 365000000 | C26: 551000000 | D26: 350000000 | E26: 356000000 | F26: 201000000 | G26: 297000000 | H26: 649000000 | I26: 802000000 | J26: 181000000 | L26: - | M26: =C26/B26-1 -> 0.50958904 | N26: =D26/C26-1 -> -0.36479129 | O26: =E26/D26-1 -> 0.017142857 | P26: =F26/E26-1 -> -0.43539326 | Q26: =G26/F26-1 -> 0.47761194 | R26: =H26/G26-1 -> 1.1851852 | S26: =I26/H26-1 -> 0.2357473 | T26: =J26/I26-1 -> -0.77431421
I27: =I26/H26-1 -> 0.2357473
A29: Наименование показателя | B29: 2012 | C29: 2013 | D29: 2014 | E29: 2015 | F29: 2016 | G29: 2017 | H29: 2018 | I29: 2019 | J29: 2020
A30: Реализация нефти и газа, нефтепродуктов и нефтехимии | B30: =B3/$B$6 -> 0.97895759 | C30: =C3/$C$6 -> 0.98508735 | D30: =D3/$D$6 -> 0.9885517 | E30: =E3/$E$6 -> 0.98466019 | F30: =F3/$F$6 -> 0.9797514 | G30: =G3/$G$6 -> 0.97721982 | H30: =H3/$H$6 -> 0.98033503 | I30: =I3/$I$6 -> 0.97856155 | J30: =J3/$J$6 -> 0.9775925
A31: Вспомогательные услуги и прочая реализация | B31: =B4/$B$6 -> 0.013596633 | C31: =C4/$C$6 -> 0.012356199 | D31: =D4/$D$6 -> 0.01362893 | E31: =E4/$E$6 -> 0.013592233 | F31: =F4/$F$6 -> 0.015036087 | G31: =G4/$G$6 -> 0.012803459 | H31: =H4/$H$6 -> 0.0097110949 | I31: =I4/$I$6 -> 0.009912402 | J31: =J4/$J$6 -> 0.013375022
A32: Доход от совместных и ассоциированных предприятий | B32: =B5/$B$6 -> 0.0074457753 | C32: =C5/$C$6 -> 0.002556455 | D32: =D5/$D$6 -> -0.0021806287 | E32: =E5/$E$6 -> 0.0017475728 | F32: =F5/$F$6 -> 0.00521251 | G32: =G5/$G$6 -> 0.009976721 | H32: =H5/$H$6 -> 0.0099538723 | I32: =I5/$I$6 -> 0.011526049 | J32: =J5/$J$6 -> 0.0090324822
A33: Итого выручка от реализации и доход от совместных и ассоциированных предприятий | B33: =B6/$B$6 -> 1 | C33: =C6/$C$6 -> 1 | D33: =D6/$D$6 -> 1 | E33: =E6/$E$6 -> 1 | F33: =F6/$F$6 -> 1 | G33: =G6/$G$6 -> 1 | H33: =H6/$H$6 -> 1 | I33: =I6/$I$6 -> 1 | J33: =J6/$J$6 -> 1
A34: Затраты и расходы
A35: Производственные и операционные расходы | B35: =ABS(B8/$B$6) -> 0.079961152 | C35: =ABS(C8/$C$6) -> 0.082871751 | D35: =ABS(D8/$D$6) -> 0.08522624 | E35: =ABS(E8/$E$6) -> 0.11165049 | F35: =ABS(F8/$F$6) -> 0.11206897 | G35: =ABS(G8/$G$6) -> 0.10093116 | H35: =ABS(H8/$H$6) -> 0.077931537 | I35: =ABS(I8/$I$6) -> 0.082411249 | J35: =ABS(J8/$J$6) -> 0.13322911
A36: Стоимость приобретенной нефти, газа, нефтепродуктов и услуг по переработке нефти | B36: =ABS(B9/$B$6) -> 0.10326967 | C36: =ABS(C9/$C$6) -> 0.092032382 | D36: =ABS(D9/$D$6) -> 0.089950936 | E36: =ABS(E9/$E$6) -> 0.10291262 | F36: =ABS(F9/$F$6) -> 0.12309543 | G36: =ABS(G9/$G$6) -> 0.13917526 | H36: =ABS(H9/$H$6) -> 0.13340617 | I36: =ABS(I9/$I$6) -> 0.18049793 | J36: =ABS(J9/$J$6) -> 0.12002779
A37: Общехозяйственные и административные расходы | B37: =ABS(B10/$B$6) -> 0.022013597 | C37: =ABS(C10/$C$6) -> 0.023647209 | D37: =ABS(D10/$D$6) -> 0.020715973 | E37: =ABS(E10/$E$6) -> 0.025242718 | F37: =ABS(F10/$F$6) -> 0.025862069 | G37: =ABS(G10/$G$6) -> 0.028599933 | H37: =ABS(H10/$H$6) -> 0.020271911 | I37: =ABS(I10/$I$6) -> 0.023052098 | J37: =ABS(J10/$J$6) -> 0.022060101
A38: Тарифы за пользование нефтепроводом и расходы на транспортировку | B38: =ABS(B11/$B$6) -> 0.078018776 | C38: =ABS(C11/$C$6) -> 0.083510865 | D38: =ABS(D11/$D$6) -> 0.085589678 | E38: =ABS(E11/$E$6) -> 0.10524272 | F38: =ABS(F11/$F$6) -> 0.11527666 | G38: =ABS(G11/$G$6) -> 0.099102095 | H38: =ABS(H11/$H$6) -> 0.077445982 | I38: =ABS(I11/$I$6) -> 0.084485938 | J38: =ABS(J11/$J$6) -> 0.11481674
A39: Затраты, связанные с разведкой запасов нефти и газа | B39: =ABS(B12/$B$6) -> 0.0074457753 | C39: =ABS(C12/$C$6) -> 0.0036216447 | D39: =ABS(D12/$D$6) -> 0.0034526622 | E39: =ABS(E12/$E$6) -> 0.0025242718 | F39: =ABS(F12/$F$6) -> 0.0028067362 | G39: =ABS(G12/$G$6) -> 0.0024941802 | H39: =ABS(H12/$H$6) -> 0.0013352756 | I39: =ABS(I12/$I$6) -> 0.0012678654 | J39: =ABS(J12/$J$6) -> 0.0026055237
A40: Износ, истощение и амортизация | B40: =ABS(B13/$B$6) -> 0.066688249 | C40: =ABS(C13/$C$6) -> 0.083510865 | D40: =ABS(D13/$D$6) -> 0.084317645 | E40: =ABS(E13/$E$6) -> 0.087378641 | F40: =ABS(F13/$F$6) -> 0.096631917 | G40: =ABS(G13/$G$6) -> 0.097439308 | H40: =ABS(H13/$H$6) -> 0.077081816 | I40: =ABS(I13/$I$6) -> 0.079183956 | J40: =ABS(J13/$J$6) -> 0.11516415
A41: Налоги, кроме налога на прибыль | B41: =ABS(B14/$B$6) -> 0.21754613 | C41: =ABS(C14/$C$6) -> 0.21815083 | D41: =ABS(D14/$D$6) -> 0.21715428 | E41: =ABS(E14/$E$6) -> 0.24796117 | F41: =ABS(F14/$F$6) -> 0.25982358 | G41: =ABS(G14/$G$6) -> 0.31908879 | H41: =ABS(H14/$H$6) -> 0.32787084 | I41: =ABS(I14/$I$6) -> 0.30728446 | J41: =ABS(J14/$J$6) -> 0.36842105
A42: Экспортная пошлина | B42: =ABS(B15/$B$6) -> 0.29168016 | C42: =ABS(C15/$C$6) -> 0.29441841 | D42: =ABS(D15/$D$6) -> 0.30583318 | E42: =ABS(E15/$E$6) -> 0.17961165 | F42: =ABS(F15/$F$6) -> 0.13171612 | G42: =ABS(G15/$G$6) -> 0.10941137 | H42: =ABS(H15/$H$6) -> 0.1287934 | I42: =ABS(I15/$I$6) -> 0.091401568 | J42: =ABS(J15/$J$6) -> 0.058016328
A43: Итого затраты и расходы | B43: =ABS(B16/$B$6) -> 0.8666235 | C43: =ABS(C16/$C$6) -> 0.88176395 | D43: =ABS(D16/$D$6) -> 0.8922406 | E43: =ABS(E16/$E$6) -> 0.86252427 | F43: =ABS(F16/$F$6) -> 0.86728148 | G43: =ABS(G16/$G$6) -> 0.8962421 | H43: =ABS(H16/$H$6) -> 0.84413693 | I43: =ABS(I16/$I$6) -> 0.84958506 | J43: =ABS(J16/$J$6) -> 0.9343408
...

Sheet сок+фин.устойчивость
A1: Показатель | B1: 2018 | C1: 2019 | D1: 2020
A2: Собственный оборотный капитал (СОК)=оборотные активы-текущие пассивы
A3: Оборотные активы | B3: =BS!H12 -> 3022000000 | C3: =BS!I12 -> 2396000000 | D3: =BS!J12 -> 2922000000
A4: Текущие пассивы | B4: =BS!H35 -> 2874000000 | C4: =BS!I35 -> 2755000000 | D4: =BS!J35 -> 3092000000
A5: СОК | B5: =B3-B4 -> 148000000 | C5: =C3-C4 -> -359000000 | D5: =D3-D4 -> -170000000
A6: Перманентный капитал (ПК) = Собственный оборотный капитал (СОК) + Долгосрочные обязательства (ДО)
A7: Долгосрочные обязательства | B7: =BS!H42 -> 5612000000 | C7: =BS!I42 -> 5042000000 | D7: =BS!J42 -> 6771000000
A8: ПК | B8: =B5+B7 -> 5760000000 | C8: =C5+C7 -> 4683000000 | D8: =D5+D7 -> 6601000000
A9: Общая величина основных источников формирования запасов (ОИФ) = Собственный оборотный капитал (СОК) + Долгосрочные обязательства (ДО) + Краткосрочные обязательства (КО)
A10: Текущие пассивы | B10: =B4 -> 2874000000 | C10: =C4 -> 2755000000 | D10: =D4 -> 3092000000
A11: ОИФ | B11: =B8+B10 -> 8634000000 | C11: =C5+C7+C10 -> 7438000000 | D11: =D5+D7+D10 -> 9693000000
A14: Показатель | B14: 2018 | C14: 2019 | D14: 2020
A15: Δ СОС = СОК – ПЗ
A16: Запасы | B16: =BS!H10 -> 393000000 | C16: =BS!I10 -> 438000000 | D16: =BS!J10 -> 361000000
A17: Δ СОК | B17: =B5-B16 -> -245000000 | C17: =C5-C16 -> -797000000 | D17: =D5-D16 -> -531000000
A18: Δ ПК = ПК – ПЗ
A19: Δ ПК | B19: =B8-B16 -> 5367000000 | C19: =C8-C16 -> 4245000000 | D19: =D8-D16 -> 6240000000
A20: Δ ОИФ = ОИ – ПЗ
A21: Δ ОИФ | B21: =B11-B16 -> 8241000000 | C21: =C11-C16 -> 7000000000 | D21: =D11-D16 -> 9332000000
A23: Δ СОК ≥ 0 (т.е. ПЗ ≤ СОК) – абсолютная финансовая устойчивость Δ СОК <0, Δ ПК ≥ 0 (т.е. СОК ≤ ПЗ ≤ ДИФ) – нормальная финансовая устойчивость Δ СОК <0, Δ ПК < 0, Δ ОИ ≥ 0 (т.е. ДИФ ≤ ПЗ ≤ ОИФ) – неустойчивое финансовое состояние Δ СОК <0, Δ ПК < 0, Δ ОИ < 0 (т.е. ОИФ ≤ ПЗ) – кризисное финансовое состояние
A26: Финансовая устойчивость | B26: Нормальная | C26: Нормальная | D26: Нормальная

Sheet фин.коэффициенты
A1: Показатель | B1: Рекомендуемое значение | C1: 2018 | D1: 2019 | E1: 2020
A2: К. фининансовой независимости (автономии)=СК/А
A3: Капитал | B3: - | C3: =BS!H52 -> 4677000000 | D3: =BS!I52 -> 5149000000 | E3: =BS!J52 -> 5487000000
A4: Активы | B4: - | C4: =BS!H25 -> 13163000000 | D4: =BS!I25 -> 12946000000 | E4: =BS!J25 -> 15350000000
A5: Кфн | B5: >0,5 | C5: =C3/C4 -> 0.35531414 | D5: =D3/D4 -> 0.39772903 | E5: =E3/E4 -> 0.35745928
A6: Значение показателя ниже 0,5, что говорит о высокой финансовой зависимости и возможном наличии проблем с платежеспособностью
A7: К. зависимости=О/А
A8: Долгосрочные обязательства | B8: - | C8: =BS!C99 -> 5612000000 | D8: =BS!D99 -> 5042000000 | E8: =BS!E99 -> 6771000000
A9: Краткочрочные обязательства | B9: - | C9: =BS!C92 -> 2874000000 | D9: =BS!D92 -> 2755000000 | E9: =BS!E92 -> 3092000000
A10: Активы | B10: - | C10: =C4 -> 13163000000 | D10: =D4 -> 12946000000 | E10: =E4 -> 15350000000
A11: Кз | B11: <0,8 | C11: =(C8+C9)/C10 -> 0.64468586 | D11: =(D8+D9)/D10 -> 0.60227097 | E11: =(E8+E9)/E10 -> 0.64254072
A12: Заемные средства составляют примерно 60-65% в структуре капитала, что является на 10-15% выше оптимального значения, но находится в пределах нормы
A13: К. соотношения заемного и собственного капитала=ЗК/СК
A14: =A8 -> Долгосрочные обязательства | B14: - | C14: =C8 -> 5612000000 | D14: =D8 -> 5042000000 | E14: =E8 -> 6771000000
A15: =A9 -> Краткочрочные обязательства | B15: - | C15: =C9 -> 2874000000 | D15: =D9 -> 2755000000 | E15: =E9 -> 3092000000
A16: Капитал | B16: - | C16: =BS!C109 -> 4677000000 | D16: =BS!D109 -> 5149000000 | E16: =BS!E109 -> 5487000000
A17: Ксф | B17: <0,7 | C17: =(C14+C15)/C16 -> 1.8144109 | D17: =(D14+D15)/D16 -> 1.5142746 | E17: =(E14+E15)/E16 -> 1.7975214
A18: Значение показателя значительно превышает рекомендуемое, что свидетельствует об усилении зависимости предприятия от внешних инвесторов и кредиторов, сигнализирует о том, что финансовая устойчивость предприятия вызывает сомнение, о росте риска инвесторов
A19: К. обеспеченности собственным оборотным капиталом=СОК/ОА
A20: СОК | B20: - | C20: ='сок+фин.устойчивость'!B5 -> 148000000 | D20: ='сок+фин.устойчивость'!C5 -> -359000000 | E20: ='сок+фин.устойчивость'!D5 -> -170000000
A21: Оборотные активы | B21: - | C21: =BS!H12 -> 3022000000 | D21: =BS!I12 -> 2396000000 | E21: =BS!J12 -> 2922000000
A22: Ко | B22: >0,1 | C22: =C20/C21 -> 0.048974189 | D22: =D20/D21 -> -0.14983306 | E22: =E20/E21 -> -0.058179329
A23: Отрицательные значения говорят о том, что все оборотные, а также часть внеоборотных активов созданы за счет кредитов и различных займов, это свидетельствует о низкой финансовой устойчивости
A24: К. маневренности=СОК/СК
A25: СОК | B25: - | C25: =C20 -> 148000000 | D25: =D20 -> -359000000 | E25: =E20 -> -170000000
A26: =A3 -> Капитал | B26: - | C26: =C16 -> 4677000000 | D26: =D16 -> 5149000000 | E26: =E16 -> 5487000000
A27: Км | B27: 0,2-0,5 | C27: =C25/C26 -> 0.031644216 | D27: =D25/D26 -> -0.069722276 | E27: =E25/E26 -> -0.030982322
A28: Отрицательный коэффициент маневренности означает низкую финансовую устойчивость в сочетании с тем, что средства вложены в медленно реализуемые активы (основные средства), а оборотный капитал формировался за счет заемных средств.
A29: К. соотношения мобильных и иммобилизованных активов=ОА/ВОА
A30: Оборотные активы | B30: - | C30: =C21 -> 3022000000 | D30: =D21 -> 2396000000 | E30: =E21 -> 2922000000
A31: Внеоборотные активы | B31: - | C31: =BS!H23 -> 10141000000 | D31: =BS!I23 -> 10550000000 | E31: =BS!J23 -> 12428000000
A32: Кс | B32: - | C32: =C30/C31 -> 0.29799823 | D32: =D30/D31 -> 0.227109 | E32: =E30/E31 -> 0.23511426
A33: Значение показателя индивидуально для каждого предприятия, чем выше значение, тем больше средств авансируется в оборотные (мобильные) активы
A34: К. имущества производственного назначения=(ВОА+З)/А
A35: =A31 -> Внеоборотные активы | B35: - | C35: =C31 -> 10141000000 | D35: =D31 -> 10550000000 | E35: =E31 -> 12428000000
A36: Запасы | B36: - | C36: ='сок+фин.устойчивость'!B16 -> 393000000 | D36: ='сок+фин.устойчивость'!C16 -> 438000000 | E36: ='сок+фин.устойчивость'!D16 -> 361000000
A37: =A4 -> Активы | B37: - | C37: =C4 -> 13163000000 | D37: =D4 -> 12946000000 | E37: =E4 -> 15350000000
A38: Кипн | B38: >0,6 | C38: =(C35+C36)/C37 -> 0.80027349 | D38: =(D35+D36)/D37 -> 0.84875637 | E38: =(E35+E36)/E37 -> 0.83315961
A39: Значение показателя выше нормативного, что говорит об отсутствии необходимости привлечения заемных средств для пополнения имущества производственного назначения
A40: К. обеспеченности запасов=СОК/З
...

Sheet ликвидность баланса
A1: Активы | F1: Пассивы
A2: Название группы | F2: Название группы
B3: Расчет | C3: 2018 | D3: 2019 | E3: 2020 | G3: Расчет | H3: 2018 | I3: 2019 | J3: 2020
A4: Наиболее ликвидные активы (А1) | B4: ДС+КФВ | C4: =BS!H5+BS!H6+BS!H7 -> 1477000000 | D4: =BS!I5+BS!I6+BS!I7 -> 739000000 | E4: =BS!J5+BS!J6+BS!J7 -> 1640000000 | F4: Наиболее срочные обязательства (П1) | G4: КЗ | H4: =BS!H28 -> 1130000000 | I4: =BS!I28 -> 1162000000 | J4: =BS!J28 -> 1546000000
A5: Быстро реализуемые активы (А2) | B5: ДЗ | C5: =BS!H8 -> 642000000 | D5: =BS!I8 -> 620000000 | E5: =BS!J8 -> 468000000 | F5: Краткосрочные пассивы (П2) | G5: КО-КЗ | H5: =BS!H35-BS!H28 -> 1744000000 | I5: =BS!I35-BS!I28 -> 1593000000 | J5: =BS!J35-BS!J28 -> 1546000000
A6: Медленно реализуемые активы (А3) | B6: Запасы + Прочие ВНА+ДФВ | C6: =BS!H10+BS!H17+BS!H18+BS!H19 -> 1606000000 | D6: =BS!I10+BS!I17+BS!I18+BS!I19 -> 1759000000 | E6: =BS!J10+BS!J17+BS!J18+BS!J19 -> 1845000000 | F6: Долгосрочные пассивы (П3) | G6: Долгосрочные обязательства | H6: =BS!H42 -> 5612000000 | I6: =BS!I42 -> 5042000000 | J6: =BS!J42 -> 6771000000
A7: Трудно реализуемые активы (А4) | B7: ВНА | C7: =BS!H23 -> 10141000000 | D7: =BS!I23 -> 10550000000 | E7: =BS!J23 -> 12428000000 | F7: Постоянные пассивы (П4) | G7: Капитал | H7: =BS!H52 -> 4677000000 | I7: =BS!I52 -> 5149000000 | J7: =BS!J52 -> 5487000000
C8: А1>П1 | D8: А1<П1 | E8: А1>П1
C9: A2<П2 | D9: A2<П2 | E9: A2<П2
C10: A3<П3 | D10: A3<П3 | E10: A3<П3
C11: А4>П4 | D11: А4>П4 | E11: А4>П4

Sheet коэффициенты ликвидности
A1: Показатель | B1: Рекомендуемое значение | C1: 2018 | D1: 2019 | E1: 2020
A2: общий показатель ликвидности=(ДС+КВФ+ДЗ+З)/(КО)
A3: ДС | C3: =BS!H5 -> 832000000 | D3: =BS!I5 -> 228000000 | E3: =BS!J5 -> 806000000
A4: Прочие оборотные фин активы | C4: =BS!H7 -> 633000000 | D4: =BS!I7 -> 501000000 | E4: =BS!J7 -> 817000000
A5: ДЗ | C5: =BS!H8 -> 642000000 | D5: =BS!I8 -> 620000000 | E5: =BS!J8 -> 468000000
A6: ЗП | C6: =BS!H10 -> 393000000 | D6: =BS!I10 -> 438000000 | E6: =BS!J10 -> 361000000
A7: Краткосрочные обязательства | C7: =BS!H35 -> 2874000000 | D7: =BS!I35 -> 2755000000 | E7: =BS!J35 -> 3092000000
A8: Общая ликвидность | C8: =(C3+C4+C5+C6)/C7 -> 0.86986778 | D8: =(D3+D4+D5+D6)/D7 -> 0.64863884 | E8: =(E3+E4+E5+E6)/E7 -> 0.79301423
A9: Значение показателя ниже 1-2, что говорит о недостаточности оборотных средств для покрытия краткосрочных обязательств
A12: Показатель | B12: Рекомендуемое значение | C12: 2018 | D12: 2019 | E12: 2020
A13: К. абсолютной ликвидности=(ДС+КФВ)/(КО)
A14: =A3 -> ДС | B14: - | C14: =C3 -> 832000000 | D14: =D3 -> 228000000 | E14: =E3 -> 806000000
A15: =A4 -> Прочие оборотные фин активы | B15: - | C15: =C4 -> 633000000 | D15: =D4 -> 501000000 | E15: =E4 -> 817000000
A16: =A7 -> Краткосрочные обязательства | B16: - | C16: =C7 -> 2874000000 | D16: =D7 -> 2755000000 | E16: =E7 -> 3092000000
A17: Кабслик | B17: >0,2 | C17: =(C14+C15)/C16 -> 0.50974252 | D17: =(D14+D15)/D16 -> 0.2646098 | E17: =(E14+E15)/E16 -> 0.52490298
A18: Значение показателя выше рекомендуемого, что говорит о полном покрытии краткосрочных обязательств за счет денежных средств и краткосрочных финансовых вложений
A19: K. срочной (быстрой) ликвидности=(ДС+КФВ+ДЗ)/(КО)
A20: =A3 -> ДС | B20: - | C20: =C14 -> 832000000 | D20: =D14 -> 228000000 | E20: =E14 -> 806000000
A21: =A4 -> Прочие оборотные фин активы | B21: - | C21: =C15 -> 633000000 | D21: =D15 -> 501000000 | E21: =E15 -> 817000000
A22: =A5 -> ДЗ | B22: - | C22: =C5 -> 642000000 | D22: =D5 -> 620000000 | E22: =E5 -> 468000000
A23: =A7 -> Краткосрочные обязательства | B23: - | C23: =C16 -> 2874000000 | D23: =D16 -> 2755000000 | E23: =E16 -> 3092000000
A24: Ксрлик | B24: >1 | C24: =(C20+C21+C22)/C23 -> 0.73312457 | D24: =(D20+D21+D22)/D23 -> 0.48965517 | E24: =(E20+E21+E22)/E23 -> 0.67626132
A25: Значение показателя ниже 1, что говорит о неполном покрытии краткосрочных обязательств за счет денежных средств, краткосрочных финансовых вложений и дебиторской задолженности, о неспособность компании погашать свои текущие обязательства в случае возникновения сложностей с реализацией продукции
A26: К. текущей (общей) ликвидности=(ОА)/(КО)
A27: ОА | B27: - | C27: =BS!H12 -> 3022000000 | D27: =BS!I12 -> 2396000000 | E27: =BS!J12 -> 2922000000
A28: =A7 -> Краткосрочные обязательства | B28: - | C28: =C7 -> 2874000000 | D28: =D7 -> 2755000000 | E28: =E7 -> 3092000000
A29: Ктеклик | B29: >2 | C29: =C27/C28 -> 1.0514962 | D29: =D27/D28 -> 0.86969147 | E29: =E27/E28 -> 0.9450194
A30: Значение ниже 1 говорит о высоком финансовом риске, связанном с тем, что предприятие не в состоянии стабильно оплачивать текущие счета

Sheet коэффициенты оборачиваемости
A1: Показатель | B1: 2018 | C1: 2019 | D1: 2020
A2: К. оборачиваемости активов (ресурсоотдача)=В/А
A3: Выручка | B3: =IS!H6 -> 8238000000 | C3: =IS!I6 -> 8676000000 | D3: =IS!J6 -> 5757000000
A4: Валюта баланса | B4: =BS!H25 -> 13163000000 | C4: =BS!I25 -> 12946000000 | D4: =BS!J25 -> 15350000000
A5: Коа | B5: =B3/B4 -> 0.62584517 | C5: =C3/C4 -> 0.67016839 | D5: =D3/D4 -> 0.37504886
A6: Па | B6: =365/B5 -> 583.21134 | C6: =365/C5 -> 544.63923 | D6: =365/D5 -> 973.20653
A7: К. оборачиваемости собственного капитала=В/СК
A8: Выручка | B8: =B3 -> 8238000000 | C8: =C3 -> 8676000000 | D8: =D3 -> 5757000000
A9: СК | B9: =BS!H52 -> 4677000000 | C9: =BS!I52 -> 5149000000 | D9: =BS!J52 -> 5487000000
A10: Коск | B10: =B8/B9 -> 1.7613855 | C10: =C8/C9 -> 1.6849874 | D10: =D8/D9 -> 1.0492072
A11: Пск | B11: =365/B10 -> 207.22323 | C11: =365/C10 -> 216.61883 | D11: =365/D10 -> 347.88171
A12: К. отдачи внеоборотных активов=В/ВНА
A13: Выручка | B13: =B3 -> 8238000000 | C13: =C3 -> 8676000000 | D13: =D3 -> 5757000000
A14: ВНА | B14: =BS!H23 -> 10141000000 | C14: =BS!I23 -> 10550000000 | D14: =BS!J23 -> 12428000000
A15: Ковна | B15: =B13/B14 -> 0.81234592 | C15: =C13/C14 -> 0.82236967 | D15: =D13/D14 -> 0.46322819
A16: Пвна | B16: =365/B15 -> 449.31597 | C16: =365/C15 -> 443.83933 | D16: =365/D15 -> 787.94858
A17: К. оборачиваемости оборотных активов=В/ОА
A18: Выручка | B18: =B3 -> 8238000000 | C18: =C3 -> 8676000000 | D18: =D3 -> 5757000000
A19: ОА | B19: =BS!H12 -> 3022000000 | C19: =BS!I12 -> 2396000000 | D19: =BS!J12 -> 2922000000
A20: Кооа | B20: =B18/B19 -> 2.7260093 | C20: =C18/C19 -> 3.6210351 | D20: =D18/D19 -> 1.9702259
A21: Поа | B21: =365/B20 -> 133.89536 | C21: =365/C20 -> 100.79991 | D21: =365/D20 -> 185.25795
A22: К. оборачиваемости основных средств (фондоотдача)=В/ОС
A23: Выручка | B23: =B18 -> 8238000000 | C23: =C18 -> 8676000000 | D23: =D18 -> 5757000000
A24: Основные средства | B24: =BS!H14 -> 8445000000 | C24: =BS!I14 -> 8706000000 | D24: =BS!J14 -> 10401000000
A25: Коос | B25: =B23/B24 -> 0.97548845 | C25: =C23/C24 -> 0.9965541 | D25: =D23/D24 -> 0.55350447
A26: Пос | B26: =365/B25 -> 374.17152 | C26: =365/C25 -> 366.2621 | D26: =365/D25 -> 659.4346
A27: К. оборачиваемости перманентного капитала=В/ПК
A28: Выручка | B28: =B23 -> 8238000000 | C28: =C23 -> 8676000000 | D28: =D23 -> 5757000000
A29: ПК | B29: ='сок+фин.устойчивость'!B8 -> 5760000000 | C29: ='сок+фин.устойчивость'!C8 -> 4683000000 | D29: ='сок+фин.устойчивость'!D8 -> 6601000000
A30: Копк | B30: =B28/B29 -> 1.4302083 | C30: =C28/C29 -> 1.8526586 | D30: =D28/D29 -> 0.87214058
A31: Ппк | B31: =365/B30 -> 255.20757 | C31: =365/C30 -> 197.01418 | D31: =365/D30 -> 418.51051
A32: К. оборачиваемости запасов=В/Запасы
A33: =A28 -> Выручка | B33: =B28 -> 8238000000 | C33: =C28 -> 8676000000 | D33: =D28 -> 5757000000
A34: Запасы | B34: =BS!H10 -> 393000000 | C34: =BS!I10 -> 438000000 | D34: =BS!J10 -> 361000000
A35: Коз | B35: =B33/B34 -> 20.961832 | C35: =C33/C34 -> 19.808219 | D35: =D33/D34 -> 15.947368
A36: Пз | B36: =365/B35 -> 17.4126 | C36: =365/C35 -> 18.426694 | D36: =365/D35 -> 22.887789
A37: среднее значение | B37: =AVERAGE(B36:D36) -> 19.575694
A38: К. оборачиваемости дебиторской задолженности=В/ДЗ
A39: Выручка | B39: =B28 -> 8238000000 | C39: =C28 -> 8676000000 | D39: =D28 -> 5757000000
A40: Дебиторская задолженность | B40: =BS!H8 -> 642000000 | C40: =BS!I8 -> 620000000 | D40: =BS!J8 -> 468000000
...

Sheet коэффициенты рентабельности
A1: Показатель | B1: 2018 | C1: 2019 | D1: 2020
A2: Рентабельность продаж=Прибыль от продаж/Выручка | E2: Коэффициент рентабельности продаж (англ. Return On Sales, ROS) – показатель отражающий эффективность продаж. Рассчитывается как отношение прибыли от продаж к выручке.
A3: EBIT | B3: =IS!H17 -> 1284000000 | C3: =IS!I17 -> 1305000000 | D3: =IS!J17 -> 378000000
A4: Выручка | B4: =IS!H6 -> 8238000000 | C4: =IS!I6 -> 8676000000 | D4: =IS!J6 -> 5757000000
A5: =A13 -> Чистая прибыль | B5: =B13 -> 649000000 | C5: =C13 -> 802000000 | D5: =D13 -> 181000000
A6: ROS (по EBIT) | B6: =B3/B4 -> 0.15586307 | C6: =C3/C4 -> 0.15041494 | D6: =D3/D4 -> 0.065659197
A7: ROS (по чистой прибыли) | B7: =B5/B4 -> 0.078781258 | C7: =C5/C4 -> 0.092438912 | D7: =D5/D4 -> 0.031439986
A8: Рентабельность собственного капитала=Чистая прибыль/Собственный капитал | E8: Коэффициент рентабельности собственного капитала (англ. Return On Equity, ROE) – показатель отражающий эффективность и доходность использования собственного капитала. Данный коэффициент часто используется инвесторами для оценки капиталоемких предприятий и отражает качество управления собственным капиталом.
A9: Чистая прибыль | B9: =IS!H26 -> 649000000 | C9: =IS!I26 -> 802000000 | D9: =IS!J26 -> 181000000
A10: Капитал | B10: =BS!H52 -> 4677000000 | C10: =BS!I52 -> 5149000000 | D10: =BS!J52 -> 5487000000
A11: ROЕ | B11: =B9/B10 -> 0.13876417 | C11: =C9/C10 -> 0.1557584 | D11: =D9/D10 -> 0.03298706
A12: Рентабельность активов=Чистая прибыль/Активы | E12: Коэффициент рентабельности активов (англ. Return On Asset, ROA) – показатель эффективности использования предприятием активов и рассчитывается как отношение чистой прибыли предприятия (после налогообложения) к величине активов. Другими словами рентабельность активов (ROA) отражает доходность, полученную как с помощью собственного, так и заемного капитала.
A13: Чистая прибыль | B13: =IS!H26 -> 649000000 | C13: =IS!I26 -> 802000000 | D13: =IS!J26 -> 181000000
A14: Валюта баланса | B14: =BS!H25 -> 13163000000 | C14: =BS!I25 -> 12946000000 | D14: =BS!J25 -> 15350000000
A15: ROА | B15: =B13/B14 -> 0.04930487 | C15: =C13/C14 -> 0.061949637 | D15: =D13/D14 -> 0.011791531
A16: Рентабельность инвестированного капитала=Чистая прибыль/(Капитал+ДО) | E16: Коэффициент рентабельности на инвестиционный капитал (англ. Return On Invested Capital, ROIC, ROI) – показатель отражающий прибыльность предприятия на инвестиционный капитал. Коэффициент рентабельности инвестиционного капитала используется инвесторами для оценки эффективности предприятия создавать добавленную стоимости на вложенный капитал. Если данный показатель высок, то предприятие инвестиционно привлекательно для инвесторов.
A17: Чистая прибыль | B17: =B9 -> 649000000 | C17: =C9 -> 802000000 | D17: =D9 -> 181000000
A18: Капитал | B18: =B10 -> 4677000000 | C18: =C10 -> 5149000000 | D18: =D10 -> 5487000000
A19: ДО | B19: =BS!H42 -> 5612000000 | C19: =BS!I42 -> 5042000000 | D19: =BS!J42 -> 6771000000
A20: ROIC | B20: =B17/(B18+B19) -> 0.063077073 | C20: =C17/(C18+C19) -> 0.078696889 | D20: =D17/(D18+D19) -> 0.014765867
A21: Рентабельность на капитал=Операционная прибыль после налога (NOPAT)/(СК+ЗК)
A22: =IS!A17 -> Операционная прибыль | B22: =IS!H17 -> 1284000000 | C22: =IS!I17 -> 1305000000 | D22: =IS!J17 -> 378000000
A23: NOPAT=EBIT*(1-t) | B23: =B22*(1-0.2) -> 1027200000 | C23: =C22*(1-0.2) -> 1044000000 | D23: =D22*(1-0.2) -> 302400000
A24: D+E | B24: =BS!H29+BS!H29+BS!H52 -> 6633000000 | C24: =BS!I29+BS!I29+BS!I52 -> 6739000000 | D24: =BS!J29+BS!J29+BS!J52 -> 7083000000
A25: ROC | B25: =B23/B24 -> 0.15486205 | C25: =C23/C24 -> 0.15491913 | D25: =D23/D24 -> 0.042693774

Sheet вероятность банкротства
A1: Пятифакторная модель Альтмана (1968)
D2: Z-счет = 1,2*X1 + 1,4*X2 + 3,3*X3 + 0,6*X4 + X5
A3: Коэффициент | B3: Формула расчета | C3: Расчет по МСФО | D3: 2018 | E3: 2019 | F3: 2020
A4: X1 | B4: Х1 = Оборотный капитал/Активы | C4: (Working Capital) / Total Assets | D4: =BS!H12/BS!H25 -> 0.22958292 | E4: =BS!I12/BS!I25 -> 0.18507647 | F4: =BS!J12/BS!J25 -> 0.19035831
A5: Х2 | B5: Х2= Нераспределенная прибыль/Активы | C5: Retained Earnings / Total Assets | D5: =BS!H49/BS!H25 -> 0.27425359 | E5: =BS!I49/BS!I25 -> 0.31144755 | F5: =BS!J49/BS!J25 -> 0.26104235
A6: Х3 | B6: Х3 = Операционная прибыль/Активы | C6: EBIT / Total Assets | D6: =IS!H17/BS!H25 -> 0.097546152 | E6: =IS!I17/BS!I25 -> 0.10080334 | F6: =IS!J17/BS!J25 -> 0.024625407
A7: Х4 | B7: Х4 = Рыночная стоимость акций/ Обязательства | C7: Market value of Equity/ Book value of Total Liabilities | D7: =H7/(BS!H35+BS!H42) -> 0.36401131 | E7: =I7/(BS!I35+BS!I42) -> 0.61126074 | F7: =J7/(BS!J35+BS!J42) -> 0.43769644 | H7: 3089000000 | I7: 4766000000 | J7: 4317000000
A8: Х5 | B8: Х5 = Выручка/Активы | C8: Sales/Total Assets | D8: =IS!H6/BS!H25 -> 0.62584517 | E8: =IS!I6/BS!I25 -> 0.67016839 | F8: =IS!J6/BS!J25 -> 0.37504886
A9: Z-счет | B9: - | C9: - | D9: =1.2*D4+1.4*D5+3.3*D6+0.6*D7+D8 -> 1.8256088 | E9: =1.2*E4+1.4*E5+3.3*E6+0.6*E7+E8 -> 2.0276942 | F9: =1.2*F4+1.4*F5+3.3*F6+0.6*F7+F8 -> 1.3128198
D11: Z < 1,81 - вероятность банкротства велика
D12: 1,81 < Z < 2,675 - вероятность банкротства средняя
D13: Z =< 2,675 - вероятность банкротства 50%
D14: 2,675 < Z < 2,99 - вероятность банкротства невелика
D15: Z > 2,99 - вероятность банкротства ничтожна
A18: Модель прогнозирования банкротства предприятия Р. Лиса (Великобритания, 1972)
D19: Z=0.063*K1 + 0.092*K2 + 0.057*K3 + 0.001*K4
A20: Коэффициент | B20: Формула расчета | C20: Расчет по МСФО | D20: 2018 | E20: 2019 | F20: 2020
A21: К1 | B21: K1 = Оборотный капитал / Активы | C21: (Working Capital) / Total Assets | D21: =D4 -> 0.22958292 | E21: =E4 -> 0.18507647 | F21: =F4 -> 0.19035831
A22: К2 | B22: K2 = Прибыль до налогообложения / Активы | C22: EBIT / Total Assets | D22: =D6 -> 0.097546152 | E22: =E6 -> 0.10080334 | F22: =F6 -> 0.024625407
A23: К3 | B23: К3 = Нераспределенная прибыль / Активы | C23: Retained Earnings / Total Assets | D23: =D5 -> 0.27425359 | E23: =E5 -> 0.31144755 | F23: =F5 -> 0.26104235
A24: К4 | B24: К4 = Собственный капитал / (Краткосрочные + Долгосрочные обязательства) | C24: Value of Equity/ Book value of Total Liabilities | D24: =D7 -> 0.36401131 | E24: =E7 -> 0.61126074 | F24: =F7 -> 0.43769644
A25: Z-счет | B25: - | C25: - | D25: =0.063*D21+0.092*D22+0.057*D23+0.001*D24 -> 0.039434436 | E25: =0.063*E21+0.092*E22+0.057*E23+0.001*E24 -> 0.039297496 | F25: =0.063*F21+0.092*F22+0.057*F23+0.001*F24 -> 0.029575221
D27: Z<0.037-банкротство компании очень вероятно
D28: Z>0.037-предприятие финансово устойчивое
A32: Модель Беликова-Давыдовой (Иркутская государственная экономическая академия, 1998 г.)
C33: Z= 8.38*K1 + 1*K2 + 0.054*K3 + 0.63*K4
A34: Коэффициент | B34: Формула расчета | C34: 2018 | D34: 2019 | E34: 2020
A35: К1 | B35: K1 = Оборотный капитал / Активы | C35: =D21 -> 0.22958292 | D35: =E21 -> 0.18507647 | E35: =F21 -> 0.19035831
A36: К2 | B36: K2 = Прибыль до налогообложения / Активы | C36: =D22 -> 0.097546152 | D36: =E22 -> 0.10080334 | E36: =F22 -> 0.024625407
A37: К3 | B37: К3 = Нераспределенная прибыль / Активы | C37: =D23 -> 0.27425359 | D37: =E23 -> 0.31144755 | E37: =F23 -> 0.26104235
A38: К4 | B38: К4 = Собственный капитал / (Краткосрочные + Долгосрочные обязательства) | C38: =BS!H52/(BS!H42+BS!H35) -> 0.55114306 | D38: =BS!I52/(BS!I42+BS!I35) -> 0.6603822 | E38: =BS!J52/(BS!J42+BS!J35) -> 0.55632161
A39: Z-счет | B39: - | C39: =8.38*C35+1*C36+0.054*C37+0.63*C38 -> 2.3834809 | D39: =8.38*D35+1*D36+0.054*D37+0.63*D38 -> 2.0846031 | E39: =8.38*E35+1*E36+0.054*E37+0.63*E38 -> 1.9844069
C43: Z<0 - риск банкротства максимальный (90-100%)
C44: 0<Z<0.18 - риск банкротства высокий (60-80%)
C45: 0.18<Z<0.32 - риск банкротства средний (35-50%)
C46: 0.32<Z<0.42 - риск банкротства низкий (15-20%)
C47: Z>0.42 - риск банкротства минимальный (до 10%)
A51: Модель Савицкой прогнозирования вероятности банкротства (Белорусский государственный экономический университет)
B52: Z= 0.111*К1 + 13.23*К2 + 1.67*К3 + 0.515*К4 + 3.8*К5
A53: Коэффициент | B53: Формула расчета | C53: 2018 | D53: 2019 | E53: 2020
...

Sheet WACC
A1: <TICKER> | B1: <DATE> | C1: <CLOSE> | D1: Доходность | F1: <TICKER> | G1: <DATE> | H1: <CLOSE> | I1: Доходность
A2: ROSN | B2: 42370 | C2: 272.45 | F2: IMOEX | G2: 42370 | H2: 1784.92
A3: ROSN | B3: 42401 | C3: 287.6 | D3: =C3/C2-1 -> 0.055606533 | F3: IMOEX | G3: 42401 | H3: 1840.17 | I3: =H3/H2-1 -> 0.030953768
A4: ROSN | B4: 42430 | C4: 305.2 | D4: =C4/C3-1 -> 0.061196106 | F4: IMOEX | G4: 42430 | H4: 1871.15 | I4: =H4/H3-1 -> 0.016835401 | Q4: ВЫВОД ИТОГОВ
A5: ROSN | B5: 42461 | C5: 351 | D5: =C5/C4-1 -> 0.15006553 | F5: IMOEX | G5: 42461 | H5: 1953.05 | I5: =H5/H4-1 -> 0.043769874
A6: ROSN | B6: 42491 | C6: 316 | D6: =C6/C5-1 -> -0.0997151 | F6: IMOEX | G6: 42491 | H6: 1899.01 | I6: =H6/H5-1 -> -0.027669543 | Q6: Регрессионная статистика
A7: ROSN | B7: 42522 | C7: 330 | D7: =C7/C6-1 -> 0.044303797 | F7: IMOEX | G7: 42522 | H7: 1891.09 | I7: =H7/H6-1 -> -0.0041705942 | Q7: Множественный R | R7: 0.682141
A8: ROSN | B8: 42552 | C8: 325.5 | D8: =C8/C7-1 -> -0.013636364 | F8: IMOEX | G8: 42552 | H8: 1944.62 | I8: =H8/H7-1 -> 0.028306426 | Q8: R-квадрат | R8: 0.46531634
A9: ROSN | B9: 42583 | C9: 344.7 | D9: =C9/C8-1 -> 0.058986175 | F9: IMOEX | G9: 42583 | H9: 1971.59 | I9: =H9/H8-1 -> 0.013869034 | Q9: Нормированный R-квадрат | R9: 0.45669241
A10: ROSN | B10: 42614 | C10: 342.8 | D10: =C10/C9-1 -> -0.0055120395 | F10: IMOEX | G10: 42614 | H10: 1978 | I10: =H10/H9-1 -> 0.0032511831 | Q10: Стандартная ошибка | R10: 0.063923329
A11: ROSN | B11: 42644 | C11: 347.65 | D11: =C11/C10-1 -> 0.014148191 | F11: IMOEX | G11: 42644 | H11: 1989.64 | I11: =H11/H10-1 -> 0.0058847321 | Q11: Наблюдения | R11: 64
A12: ROSN | B12: 42675 | C12: 340.2 | D12: =C12/C11-1 -> -0.021429599 | F12: IMOEX | G12: 42675 | H12: 2104.91 | I12: =H12/H11-1 -> 0.057935104
A13: ROSN | B13: 42705 | C13: 402.8 | D13: =C13/C12-1 -> 0.18400941 | F13: IMOEX | G13: 42705 | H13: 2232.72 | I13: =H13/H12-1 -> 0.060719936 | Q13: Дисперсионный анализ
A14: ROSN | B14: 42736 | C14: 400.6 | D14: =C14/C13-1 -> -0.0054617676 | F14: IMOEX | G14: 42736 | H14: 2217.39 | I14: =H14/H13-1 -> -0.0068660647 | R14: df | S14: SS | T14: MS | U14: F | V14: Значимость F
A15: ROSN | B15: 42767 | C15: 331.1 | D15: =C15/C14-1 -> -0.17348977 | F15: IMOEX | G15: 42767 | H15: 2035.77 | I15: =H15/H14-1 -> -0.081907107 | Q15: Регрессия | R15: 1 | S15: 0.22047627 | T15: 0.22047627 | U15: 53.956415 | V15: 5.4154922e-10
A16: ROSN | B16: 42795 | C16: 323.5 | D16: =C16/C15-1 -> -0.02295379 | F16: IMOEX | G16: 42795 | H16: 1995.9 | I16: =H16/H15-1 -> -0.019584727 | Q16: Остаток | R16: 62 | S16: 0.2533439 | T16: 0.004086192
A17: ROSN | B17: 42826 | C17: 317.25 | D17: =C17/C16-1 -> -0.019319938 | F17: IMOEX | G17: 42826 | H17: 2016.71 | I17: =H17/H16-1 -> 0.010426374 | Q17: Итого | R17: 63 | S17: 0.47382017
A18: ROSN | B18: 42856 | C18: 301.55 | D18: =C18/C17-1 -> -0.049487786 | F18: IMOEX | G18: 42856 | H18: 1900.38 | I18: =H18/H17-1 -> -0.057683058
A19: ROSN | B19: 42887 | C19: 323 | D19: =C19/C18-1 -> 0.071132482 | F19: IMOEX | G19: 42887 | H19: 1879.5 | I19: =H19/H18-1 -> -0.010987276 | R19: Коэффициенты | S19: Стандартная ошибка | T19: t-статистика | U19: P-Значение | V19: Нижние 95% | W19: Верхние 95% | X19: Нижние 95,0% | Y19: Верхние 95,0%
A20: ROSN | B20: 42917 | C20: 311.3 | D20: =C20/C19-1 -> -0.03622291 | F20: IMOEX | G20: 42917 | H20: 1919.53 | I20: =H20/H19-1 -> 0.021298218 | Q20: Y-пересечение | R20: -0.0030037384 | S20: 0.0083212758 | T20: -0.3609709 | U20: 0.71934828 | V20: -0.019637732 | W20: 0.013630255 | X20: -0.019637732 | Y20: 0.013630255
A21: ROSN | B21: 42948 | C21: 304 | D21: =C21/C20-1 -> -0.023450048 | F21: IMOEX | G21: 42948 | H21: 2022.22 | I21: =H21/H20-1 -> 0.053497471 | Q21: Переменная X 1 | R21: 1.4191373 | S21: 0.19319811 | T21: 7.345503 | U21: 5.4154922e-10 | V21: 1.0329398 | W21: 1.8053348 | X21: 1.0329398 | Y21: 1.8053348
A22: ROSN | B22: 42979 | C22: 318.95 | D22: =C22/C21-1 -> 0.049177632 | F22: IMOEX | G22: 42979 | H22: 2077.19 | I22: =H22/H21-1 -> 0.027182997
A23: ROSN | B23: 43009 | C23: 318.7 | D23: =C23/C22-1 -> -0.00078382192 | F23: IMOEX | G23: 43009 | H23: 2064.31 | I23: =H23/H22-1 -> -0.0062006846
A24: ROSN | B24: 43040 | C24: 293.6 | D24: =C24/C23-1 -> -0.078757452 | F24: IMOEX | G24: 43040 | H24: 2100.62 | I24: =H24/H23-1 -> 0.017589412
A25: ROSN | B25: 43070 | C25: 291.5 | D25: =C25/C24-1 -> -0.0071525886 | F25: IMOEX | G25: 43070 | H25: 2109.74 | I25: =H25/H24-1 -> 0.0043415753 | Q25: Rf | R25: 0.0675 | S25: Кривая бескупонной доходности государственных облигаций | Банк России (cbr.ru)
A26: ROSN | B26: 43101 | C26: 343.2 | D26: =C26/C25-1 -> 0.17735849 | F26: IMOEX | G26: 43101 | H26: 2289.99 | I26: =H26/H25-1 -> 0.085437068 | Q26: b | R26: =R21 -> 1.4191373
A27: ROSN | B27: 43132 | C27: 330.5 | D27: =C27/C26-1 -> -0.037004662 | F27: IMOEX | G27: 43132 | H27: 2296.8 | I27: =H27/H26-1 -> 0.0029738121 | Q27: Rm | R27: =AVERAGE(I3:I66)*12 -> 0.14429452
A28: ROSN | B28: 43160 | C28: 313.9 | D28: =C28/C27-1 -> -0.050226929 | F28: IMOEX | G28: 43160 | H28: 2270.98 | I28: =H28/H27-1 -> -0.011241728 | Q28: Re(CAPM) | R28: =R25+R26*(R27-R25) -> 0.17648197
A29: ROSN | B29: 43191 | C29: 383 | D29: =C29/C28-1 -> 0.2201338 | F29: IMOEX | G29: 43191 | H29: 2307.02 | I29: =H29/H28-1 -> 0.015869801
A30: ROSN | B30: 43221 | C30: 385.3 | D30: =C30/C29-1 -> 0.0060052219 | F30: IMOEX | G30: 43221 | H30: 2302.88 | I30: =H30/H29-1 -> -0.0017945228
A31: ROSN | B31: 43252 | C31: 396.15 | D31: =C31/C30-1 -> 0.028159875 | F31: IMOEX | G31: 43252 | H31: 2295.95 | I31: =H31/H30-1 -> -0.0030092753 | U31: Расчет средневзвешенной процентоной ставки заемного капитала | Z31: либор usd 31.12.2020 (12 мес), % | AA31: 0.0034
A32: ROSN | B32: 43282 | C32: 419 | D32: =C32/C31-1 -> 0.057680172 | F32: IMOEX | G32: 43282 | H32: 2321.11 | I32: =H32/H31-1 -> 0.010958427 | Q32: D | R32: =BS!J29+BS!J37 -> 4608000000
A33: ROSN | B33: 43313 | C33: 435.7 | D33: =C33/C32-1 -> 0.039856802 | F33: IMOEX | G33: 43313 | H33: 2345.85 | I33: =H33/H32-1 -> 0.010658693 | Q33: Доля D | R33: =R32/R38 -> 0.4564636 | U33: Кредиты стр 83 | AA33: 0.026 | AB33: =AVERAGE(AA33:AA34) -> 0.035
A34: ROSN | B34: 43344 | C34: 493 | D34: =C34/C33-1 -> 0.13151251 | F34: IMOEX | G34: 43344 | H34: 2475.36 | I34: =H34/H33-1 -> 0.055208134 | Q34: rd | R34: =W70 -> 0.063521093 | U34: 801 | V34: =AB33+AA31 -> 0.0384 | W34: =U34/$U$70 -> 0.32680539 | X34: =W34*V34 -> 0.012549327 | AA34: 0.044
A35: ROSN | B35: 43374 | C35: 460.45 | D35: =C35/C34-1 -> -0.066024341 | F35: IMOEX | G35: 43374 | H35: 2352.71 | I35: =H35/H34-1 -> -0.049548349 | Q35: E | R35: =BS!J52 -> 5487000000 | T35: =U34+U35+U36 -> 1720 | U35: 112 | V35: =AB37 -> 0.02275 | W35: =U35/$U$70 -> 0.045695634 | X35: =W35*V35 -> 0.0010395757
A36: ROSN | B36: 43405 | C36: 423.1 | D36: =C36/C35-1 -> -0.081116299 | F36: IMOEX | G36: 43405 | H36: 2392.5 | I36: =H36/H35-1 -> 0.016912412 | Q36: Доля E | R36: =R35/R38 -> 0.5435364 | U36: 807 | V36: 0.085 | W36: =U36/$U$70 -> 0.32925337 | X36: =W36*V36 -> 0.027986536
A37: ROSN | B37: 43435 | C37: 432.5 | D37: =C37/C36-1 -> 0.02221697 | F37: IMOEX | G37: 43435 | H37: 2369.17 | I37: =H37/H36-1 -> -0.0097513062 | Q37: re | R37: =R28 -> 0.17648197 | T37: =SUM(U37:U67) -> 581 | U37: 20 | V37: 0.079 | W37: =U37/$U$70 -> 0.0081599347 | X37: =W37*V37 -> 0.00064463484 | AA37: 0.02 | AB37: =AVERAGE(AA37:AA38) -> 0.02275
A38: ROSN | B38: 43466 | C38: 411.25 | D38: =C38/C37-1 -> -0.049132948 | F38: IMOEX | G38: 43466 | H38: 2521.1 | I38: =H38/H37-1 -> 0.064127944 | Q38: D+E | R38: =R32+R35 -> 10095000000 | U38: 31 | V38: 0.073 | W38: =U38/$U$70 -> 0.012647899 | X38: =W38*V38 -> 0.00092329661 | AA38: 0.0255
A39: ROSN | B39: 43497 | C39: 398.8 | D39: =C39/C38-1 -> -0.030273556 | F39: IMOEX | G39: 43497 | H39: 2485.27 | I39: =H39/H38-1 -> -0.01421205 | Q39: WACC | R39: =R36*R37+R33*R34*0.8 -> 0.11912043 | U39: 5 | V39: 0.07 | W39: =U39/$U$70 -> 0.0020399837 | X39: =W39*V39 -> 0.00014279886
A40: ROSN | B40: 43525 | C40: 412 | D40: =C40/C39-1 -> 0.033099298 | F40: IMOEX | G40: 43525 | H40: 2497.1 | I40: =H40/H39-1 -> 0.0047600462 | U40: 26 | V40: 0.0665 | W40: =U40/$U$70 -> 0.010607915 | X40: =W40*V40 -> 0.00070542636
...

Sheet Доходный подход
A1: Отчет о прибылях и убытках МСФО, тыс.руб. | B1: ,
A2: Наименование показателя | B2: 2017 | C2: 2018 | D2: 2019 | E2: 2020
A3: Итого выручка от реализации и доход от совместных и ассоциированных предприятий, тыс.руб | B3: 6014000000 | C3: 8238000000 | D3: 8676000000 | E3: 5757000000
A4: Добыча жуд, млн.т | B4: 225.5 | C4: 230.2 | D4: 230.2 | E4: 204.5
A5: Переработка нефти, млн.т | B5: 112.8 | C5: 115 | D5: 110.2 | E5: 104
A6: Производство нефтепродуктов и нефтехимии, млн.т | B6: 109.1 | C6: 111.7 | D6: 107.5 | E6: 101.4
A7: Реализация нефти за рубежом, млн.т | B7: 121.8 | C7: 123.7 | D7: 149.4 | E7: 115.4
A8: Реализация нефти на внутреннем рынке | B8: 6.9 | C8: 5.4 | D8: 5.6 | E8: 5.2
A9: Реализация нефтепродуктов и нефтехимии за рубежом, млн.т. | B9: 71.9 | C9: 73.7 | D9: 71.1 | E9: 64.2
A10: Реализация нефтепродуктов и нефтехимии на внутреннем рынке, млн.т. | B10: 11.7 | C10: 13.7 | D10: 42 | E10: 37.9
A11: Добыча газа | B11: 68.41 | C11: 67.3 | D11: 67 | E11: 62.8
A12: Реализация газа в России | B12: 63.2
A13: Реализация газа за рубежом | B13: 0.7
A17: Общий объем реализации нефти, млн.т. | B17: =B7+B8 -> 128.7 | C17: =C7+C8 -> 129.1 | D17: 155 | E17: 120.6
A18: За рубеж | B18: 121.8 | C18: 123.7 | D18: 149.4 | E18: 115.4
A19: На внутреннем рынке | B19: 6.9 | C19: 5.4 | D19: 5.6 | E19: 5.2
A21: Общий объем реализации газа, млрд. м3 | B21: 63.9 | C21: 62 | D21: 61.77 | E21: 56.43
A22: За рубеж | B22: 0.7 | C22: 2.9 | D22: 4.85 | E22: 4.45
A23: На внутреннем рынке | B23: 63.2 | C23: 59.13 | D23: 56.92 | E23: 51.98
A24: Выручка от реализации газа, тыс.руб. | B24: 210000000 | C24: 234000000 | D24: 258800000 | E24: 239800000
B25: =B24/B3 -> 0.034918523 | C25: =C24/C3 -> 0.028404953 | D25: =D24/D3 -> 0.029829414 | E25: =E24/E3 -> 0.041653639
A27: Общий объем реализации нефтепродуктов, млн.т. | B27: =B28+B29 -> 83.4 | C27: =C28+C29 -> 87.4 | D27: =D28+D29 -> 85.6 | E27: =E28+E29 -> 77.25 | L27: MDA_RUS_4Q2020.pdf (rosneft.ru)
A28: За рубеж | B28: 71.9 | C28: 73.7 | D28: 71.1 | E28: 64.2 | L28: Анализ руководством финансового состояния и результатов деятельности Компании «Роснефть» за четвертый квартал 2018 года и 12 месяцев 2018 года (rosneft.ru)
A29: На внутреннем рынке | B29: 11.5 | C29: 13.7 | D29: 14.5 | E29: =D29*0.9 -> 13.05
C33: =C38/B38-1 -> 0.016645327 | D33: =D38/C38-1 -> 0.0080964376 | E33: =E38/D38-1 -> -0.086025344 | F33: =F38/E38-1 -> 0.0004881859 | G33: =G38/F38-1 -> 0.073172636 | H33: =H38/G38-1 -> 0.018478103 | I33: =I38/H38-1 -> 0.0089285714 | J33: =J38/I38-1 -> 0.03852064 | K33: =_xlfn.FORECAST.ETS(J37,C33:I33,C37:I37) -> 0.03852064
A34: ПРОГНОЗ ОБЪЕМА
A35: НЕФТЬ | L35: Сценарные условия, основные параметры прогноза социально-экономического развития Российской Федерации и прогнозируемые изменения цен (тарифов) на товары, услуги хозяйствующих субъектов, осуществляющих регулируемые виды деятельности в инфраструктурном секторе, на 2022 год и на плановый период 2023 и 2024 годов | Министерство экономического развития Российской Федерации (economy.gov.ru)
A37: Прогноз добычи нефти | B37: 2017 | C37: 2018 | D37: 2019 | E37: 2020 | F37: 2021 | G37: 2022 | H37: 2023 | I37: 2024 | J37: 2025 | L37: Сценарные условия, основные параметры прогноза социально-экономического развития Российской Федерации и прогнозируемые изменения цен (тарифов) на товары, услуги хозяйствующих субъектов, осуществляющих регулируемые виды деятельности в инфраструктурном секторе, на 2022 год и на плановый период 2023 и 2024 годов
A38: Добыча нефти РФ, млн.т (базовый сценарий) | B38: 546.7 | C38: 555.8 | D38: 560.3 | E38: 512.1 | F38: 512.35 | G38: 549.84 | H38: 560 | I38: 565 | J38: =I38*(1+K33) -> 586.76416 | L38: CAGR (2021-2024) | M38: =(I38/F38)^(1/4)-1 -> 0.024755899
A39: Добыча нефти Роснефть, млн.т | B39: =B4 -> 225.5 | C39: =C4 -> 230.2 | D39: =D4 -> 230.2 | E39: =E4 -> 204.5 | F39: =F38*F40 -> 209.65874 | G39: =G38*G40 -> 225.00003 | H39: =H38*H40 -> 229.1576 | I39: =I38*I40 -> 231.20365 | J39: =J38*J40 -> 240.10976
A40: Доля добычи Роснефти от добычи РФ | B40: =B39/B38 -> 0.41247485 | C40: =C39/C38 -> 0.41417776 | D40: =D39/D38 -> 0.41085133 | E40: =E39/E38 -> 0.39933607 | F40: =$B$41 -> 0.40921 | G40: =$B$41 -> 0.40921 | H40: =$B$41 -> 0.40921 | I40: =$B$41 -> 0.40921 | J40: =$B$41 -> 0.40921
A41: Средняя доля компании | B41: =AVERAGE(B40:E40) -> 0.40921
A43: Прогноз переработки нефти | B43: 2017 | C43: 2018 | D43: 2019 | E43: 2020 | F43: 2021 | G43: 2022 | H43: 2023 | I43: 2024 | J43: 2025
A44: Добыча нефти Роснефть, млн.т | B44: =B39 -> 225.5 | C44: =C39 -> 230.2 | D44: =D39 -> 230.2 | E44: =E39 -> 204.5 | F44: =F39 -> 209.65874 | G44: =G39 -> 225.00003 | H44: =H39 -> 229.1576 | I44: =I39 -> 231.20365 | J44: =J39 -> 240.10976
A45: Переработка нефти Роснефть, млн.т | B45: =B5 -> 112.8 | C45: =C5 -> 115 | D45: =D5 -> 110.2 | E45: 103.98 | F45: =F44*F46 -> 104.14594 | G45: =G44*G46 -> 111.76658 | H45: =H44*H46 -> 113.83181 | I45: =I44*I46 -> 114.84817 | J45: =J44*J46 -> 119.27219
A46: Доля переработки от добычи | B46: =B45/B44 -> 0.50022173 | C46: =C45/C44 -> 0.4995656 | D46: =D45/D44 -> 0.47871416 | E46: =E45/E44 -> 0.50845966 | F46: =$B$47 -> 0.49674029 | G46: =$B$47 -> 0.49674029 | H46: =$B$47 -> 0.49674029 | I46: =$B$47 -> 0.49674029 | J46: =$B$47 -> 0.49674029 | O46: Прогноз реализации нефтепродуктов за рубежом по видам подукции | P46: 2017 | Q46: 2018 | R46: 2019 | S46: 2020 | T46: 2021 | U46: 2022 | V46: 2023 | W46: 2024 | X46: 2025
A47: Средняя доля переработки | B47: =AVERAGE(B46:E46) -> 0.49674029 | O47: Реализация за рубеж, млн.т | P47: =B77 -> 68.1 | Q47: =C77 -> 70.1 | R47: =D77 -> 67.8 | S47: =E77 -> 62.2 | T47: =F77 -> 63.183764 | U47: =G77 -> 67.807087 | V47: =H77 -> 69.060033 | W47: =I77 -> 69.676641 | X47: 70.612584
O48: Дальнее зарубежье (Европа и Азия) | P48: =B80+B83 -> 63.7 | Q48: =C80+C83 -> 66 | R48: =D80+D83 -> 64.1 | S48: =E80+E83 -> 58.7 | T48: =F80+F83 -> 59.488444 | U48: =G80+G83 -> 63.841371 | V48: =H80+H83 -> 65.021038 | W48: =I80+I83 -> 65.601583 | X48: 70.612584
A49: Прогноз реализации нефти | B49: 2017 | C49: 2018 | D49: 2019 | E49: 2020 | F49: 2021 | G49: 2022 | H49: 2023 | I49: 2024 | J49: 2025 | O49: Автомобильный бензин | P49: 0.6 | Q49: 0.7 | R49: 1.1 | S49: 0.5 | T49: =T48*$P$50 -> 0.6797118 | U49: =U48*$P$50 -> 0.7294481 | V49: =V48*$P$50 -> 0.74292692 | W49: =W48*$P$50 -> 0.74956019 | X49: =X48*$P$50 -> 0.80681562
A50: Добыча нефти, млн.т | B50: =B44 -> 225.5 | C50: =C44 -> 230.2 | D50: =D44 -> 230.2 | E50: =E44 -> 204.5 | F50: =F44 -> 209.65874 | G50: =G44 -> 225.00003 | H50: =H44 -> 229.1576 | I50: =I44 -> 231.20365 | J50: =J44 -> 240.10976 | O50: Средняя величина реализации | P50: =AVERAGE(P49/P48,Q49/Q48,R49/R48,S49/S48) -> 0.011425947
...

Sheet Сравнительный подход
C1: https://finance.yahoo.com
C2: КУРС ДОЛЛАРА НА 31.12.2020 | D2: 73.87
A3: Общие сведения
A4: Эмитент | B4: Страна | C4: Тикер | D4: Запасы углеводородов, млрд. барр. нефтяного эквивалента на 31.12.2019 | E4: Выручка, млрд.руб. | F4: Чистая прибыль, млрд.руб | G4: Активы, млрд.руб | H4: Собственнный капитал, млрд.руб | I4: ROE | J4: ROS | K4: ROA
A7: Российские компании
A8: ПАО «НК «Роснефть» | B8: РФ | C8: ROSN | D8: 42.018 | E8: =[1]IS!J6/1000000 -> 5757 | F8: =[1]IS!J26/1000000 -> 181 | G8: =[1]BS!J25/1000000 -> 15350 | H8: =[1]BS!J52/1000000 -> 5487 | I8: =F8/H8 -> 0.03298706 | J8: =F8/E8 -> 0.031439986 | K8: =F8/G8 -> 0.011791531
A9: ПАО «Газпром» | B9: РФ | C9: GAZP | D9: 177.1 | E9: 6321 | F9: 162.407 | G9: 23352 | H9: 14804 | I9: =F9/H9 -> 0.010970481 | J9: =F9/E9 -> 0.025693245 | K9: =F9/G9 -> 0.0069547362
A10: ПАО «ЛУКОЙЛ» | B10: РФ | C10: LKOH | D10: 15.8 | E10: 5639 | F10: 16.63 | G10: 5992 | H10: 4130.76 | I10: =F10/H10 -> 0.0040258935 | J10: =F10/E10 -> 0.0029491045 | K10: =F10/G10 -> 0.0027753672
